*** Starting uWSGI 2.0.18 (64bit) on [Wed Oct 23 20:29:20 2019] ***
compiled with version: 4.8.5 20150623 (Red Hat 4.8.5-39) on 21 October 2019 12:48:53
os: Linux-3.10.0-957.21.3.el7.x86_64 #1 SMP Tue Jun 18 16:35:19 UTC 2019
nodename: VM_0_6_centos
machine: x86_64
clock source: unix
pcre jit disabled
detected number of CPU cores: 1
current working directory: /usr/local/webserver/FSS
detected binary path: /usr/local/python3/bin/uwsgi
uWSGI running as root, you can use --uid/--gid/--chroot options
*** WARNING: you are running uWSGI as root !!! (use the --uid flag) *** 
chdir() to /usr/local/webserver/FSS/
your processes number limit is 7269
your memory page size is 4096 bytes
detected max file descriptor number: 100001
lock engine: pthread robust mutexes
thunder lock: disabled (you can enable it with --thunder-lock)
uWSGI http bound on 8082 fd 3
uwsgi socket 0 bound to TCP address 127.0.0.1:8081 fd 6
uWSGI running as root, you can use --uid/--gid/--chroot options
*** WARNING: you are running uWSGI as root !!! (use the --uid flag) *** 
Python version: 3.6.1 (default, Oct 19 2019, 16:14:38)  [GCC 4.8.5 20150623 (Red Hat 4.8.5-36)]
Python main interpreter initialized at 0x1506610
uWSGI running as root, you can use --uid/--gid/--chroot options
*** WARNING: you are running uWSGI as root !!! (use the --uid flag) *** 
python threads support enabled
your server socket listen backlog is limited to 100 connections
your mercy for graceful operations on workers is 60 seconds
mapped 250128 bytes (244 KB) for 4 cores
*** Operational MODE: preforking+threaded ***
WSGI app 0 (mountpoint='') ready in 0 seconds on interpreter 0x1506610 pid: 9740 (default app)
uWSGI running as root, you can use --uid/--gid/--chroot options
*** WARNING: you are running uWSGI as root !!! (use the --uid flag) *** 
*** uWSGI is running in multiple interpreter mode ***
spawned uWSGI master process (pid: 9740)
spawned uWSGI worker 1 (pid: 9744, cores: 2)
spawned uWSGI worker 2 (pid: 9745, cores: 2)
spawned uWSGI http 1 (pid: 9746)
Wed Oct 23 20:29:49 2019 - *** PAUSE (press start to resume, if you do not have a joypad send SIGTSTP) ***
Wed Oct 23 20:29:49 2019 - *** worker 1 suspended ***
Wed Oct 23 20:29:49 2019 - *** worker 2 suspended ***
Gracefully killing worker 2 (pid: 9745)...
Gracefully killing worker 1 (pid: 9744)...
gateway "uWSGI http 1" has been buried (pid: 9746)
...gracefully killing workers...
worker 1 buried after 1 seconds
worker 2 buried after 1 seconds
binary reloading uWSGI...
chdir() to /usr/local/webserver/FSS
closing all non-uwsgi socket fds > 2 (max_fd = 100001)...
found fd 6 mapped to socket 0 (127.0.0.1:8081)
running /usr/local/python3/bin/uwsgi
[uWSGI] getting INI configuration from uwsgi.ini
*** Starting uWSGI 2.0.18 (64bit) on [Wed Oct 23 20:29:58 2019] ***
compiled with version: 4.8.5 20150623 (Red Hat 4.8.5-39) on 21 October 2019 12:48:53
os: Linux-3.10.0-957.21.3.el7.x86_64 #1 SMP Tue Jun 18 16:35:19 UTC 2019
nodename: VM_0_6_centos
machine: x86_64
clock source: unix
pcre jit disabled
detected number of CPU cores: 1
current working directory: /usr/local/webserver/FSS
detected binary path: /usr/local/python3/bin/uwsgi
uWSGI running as root, you can use --uid/--gid/--chroot options
*** WARNING: you are running uWSGI as root !!! (use the --uid flag) *** 
chdir() to /usr/local/webserver/FSS/
your processes number limit is 7269
your memory page size is 4096 bytes
detected max file descriptor number: 100001
lock engine: pthread robust mutexes
thunder lock: disabled (you can enable it with --thunder-lock)
uWSGI http bound on 8082 fd 3
uwsgi socket 0 inherited INET address 127.0.0.1:8081 fd 6
uWSGI running as root, you can use --uid/--gid/--chroot options
*** WARNING: you are running uWSGI as root !!! (use the --uid flag) *** 
Python version: 3.6.1 (default, Oct 19 2019, 16:14:38)  [GCC 4.8.5 20150623 (Red Hat 4.8.5-36)]
Python main interpreter initialized at 0x1ee1000
uWSGI running as root, you can use --uid/--gid/--chroot options
*** WARNING: you are running uWSGI as root !!! (use the --uid flag) *** 
python threads support enabled
your server socket listen backlog is limited to 100 connections
your mercy for graceful operations on workers is 60 seconds
mapped 250128 bytes (244 KB) for 4 cores
*** Operational MODE: preforking+threaded ***
WSGI app 0 (mountpoint='') ready in 0 seconds on interpreter 0x1ee1000 pid: 9740 (default app)
uWSGI running as root, you can use --uid/--gid/--chroot options
*** WARNING: you are running uWSGI as root !!! (use the --uid flag) *** 
*** uWSGI is running in multiple interpreter mode ***
gracefully (RE)spawned uWSGI master process (pid: 9740)
spawned uWSGI worker 1 (pid: 9859, cores: 2)
spawned uWSGI worker 2 (pid: 9860, cores: 2)
spawned uWSGI http 1 (pid: 9861)
Wed Oct 23 20:32:42 2019 - *** /usr/local/webserver/FSS/ has been touched... grace them all !!! ***
gateway "uWSGI http 1" has been buried (pid: 9861)
...gracefully killing workers...
Gracefully killing worker 1 (pid: 9859)...
Gracefully killing worker 2 (pid: 9860)...
worker 1 buried after 1 seconds
worker 2 buried after 1 seconds
binary reloading uWSGI...
chdir() to /usr/local/webserver/FSS
closing all non-uwsgi socket fds > 2 (max_fd = 100001)...
found fd 6 mapped to socket 0 (127.0.0.1:8081)
running /usr/local/python3/bin/uwsgi
[uWSGI] getting INI configuration from uwsgi.ini
*** Starting uWSGI 2.0.18 (64bit) on [Wed Oct 23 20:32:43 2019] ***
compiled with version: 4.8.5 20150623 (Red Hat 4.8.5-39) on 21 October 2019 12:48:53
os: Linux-3.10.0-957.21.3.el7.x86_64 #1 SMP Tue Jun 18 16:35:19 UTC 2019
nodename: VM_0_6_centos
machine: x86_64
clock source: unix
pcre jit disabled
detected number of CPU cores: 1
current working directory: /usr/local/webserver/FSS
detected binary path: /usr/local/python3/bin/uwsgi
uWSGI running as root, you can use --uid/--gid/--chroot options
*** WARNING: you are running uWSGI as root !!! (use the --uid flag) *** 
chdir() to /usr/local/webserver/FSS/
your processes number limit is 7269
your memory page size is 4096 bytes
detected max file descriptor number: 100001
lock engine: pthread robust mutexes
thunder lock: disabled (you can enable it with --thunder-lock)
uWSGI http bound on 8082 fd 3
uwsgi socket 0 inherited INET address 127.0.0.1:8081 fd 6
uWSGI running as root, you can use --uid/--gid/--chroot options
*** WARNING: you are running uWSGI as root !!! (use the --uid flag) *** 
Python version: 3.6.1 (default, Oct 19 2019, 16:14:38)  [GCC 4.8.5 20150623 (Red Hat 4.8.5-36)]
Python main interpreter initialized at 0x2493000
uWSGI running as root, you can use --uid/--gid/--chroot options
*** WARNING: you are running uWSGI as root !!! (use the --uid flag) *** 
python threads support enabled
your server socket listen backlog is limited to 100 connections
your mercy for graceful operations on workers is 60 seconds
mapped 250128 bytes (244 KB) for 4 cores
*** Operational MODE: preforking+threaded ***
WSGI app 0 (mountpoint='') ready in 1 seconds on interpreter 0x2493000 pid: 9740 (default app)
uWSGI running as root, you can use --uid/--gid/--chroot options
*** WARNING: you are running uWSGI as root !!! (use the --uid flag) *** 
*** uWSGI is running in multiple interpreter mode ***
gracefully (RE)spawned uWSGI master process (pid: 9740)
spawned uWSGI worker 1 (pid: 10465, cores: 2)
spawned uWSGI worker 2 (pid: 10466, cores: 2)
spawned uWSGI http 1 (pid: 10467)
Wed Oct 23 20:33:06 2019 - *** /usr/local/webserver/FSS/ has been touched... grace them all !!! ***
gateway "uWSGI http 1" has been buried (pid: 10467)
...gracefully killing workers...
Gracefully killing worker 1 (pid: 10465)...
Gracefully killing worker 2 (pid: 10466)...
worker 1 buried after 1 seconds
worker 2 buried after 1 seconds
binary reloading uWSGI...
chdir() to /usr/local/webserver/FSS
closing all non-uwsgi socket fds > 2 (max_fd = 100001)...
found fd 6 mapped to socket 0 (127.0.0.1:8081)
running /usr/local/python3/bin/uwsgi
[uWSGI] getting INI configuration from uwsgi.ini
*** Starting uWSGI 2.0.18 (64bit) on [Wed Oct 23 20:33:07 2019] ***
compiled with version: 4.8.5 20150623 (Red Hat 4.8.5-39) on 21 October 2019 12:48:53
os: Linux-3.10.0-957.21.3.el7.x86_64 #1 SMP Tue Jun 18 16:35:19 UTC 2019
nodename: VM_0_6_centos
machine: x86_64
clock source: unix
pcre jit disabled
detected number of CPU cores: 1
current working directory: /usr/local/webserver/FSS
detected binary path: /usr/local/python3/bin/uwsgi
uWSGI running as root, you can use --uid/--gid/--chroot options
*** WARNING: you are running uWSGI as root !!! (use the --uid flag) *** 
chdir() to /usr/local/webserver/FSS/
your processes number limit is 7269
your memory page size is 4096 bytes
detected max file descriptor number: 100001
lock engine: pthread robust mutexes
thunder lock: disabled (you can enable it with --thunder-lock)
uwsgi socket 0 inherited INET address 127.0.0.1:8081 fd 6
uWSGI running as root, you can use --uid/--gid/--chroot options
*** WARNING: you are running uWSGI as root !!! (use the --uid flag) *** 
Python version: 3.6.1 (default, Oct 19 2019, 16:14:38)  [GCC 4.8.5 20150623 (Red Hat 4.8.5-36)]
Python main interpreter initialized at 0x1d81f40
uWSGI running as root, you can use --uid/--gid/--chroot options
*** WARNING: you are running uWSGI as root !!! (use the --uid flag) *** 
python threads support enabled
your server socket listen backlog is limited to 100 connections
your mercy for graceful operations on workers is 60 seconds
mapped 250128 bytes (244 KB) for 4 cores
*** Operational MODE: preforking+threaded ***
WSGI app 0 (mountpoint='') ready in 0 seconds on interpreter 0x1d81f40 pid: 9740 (default app)
uWSGI running as root, you can use --uid/--gid/--chroot options
*** WARNING: you are running uWSGI as root !!! (use the --uid flag) *** 
*** uWSGI is running in multiple interpreter mode ***
gracefully (RE)spawned uWSGI master process (pid: 9740)
spawned uWSGI worker 1 (pid: 10546, cores: 2)
spawned uWSGI worker 2 (pid: 10547, cores: 2)
Wed Oct 23 20:33:24 2019 - *** /usr/local/webserver/FSS/ has been touched... grace them all !!! ***
...gracefully killing workers...
Gracefully killing worker 1 (pid: 10546)...
Gracefully killing worker 2 (pid: 10547)...
worker 1 buried after 1 seconds
worker 2 buried after 1 seconds
binary reloading uWSGI...
chdir() to /usr/local/webserver/FSS
closing all non-uwsgi socket fds > 2 (max_fd = 100001)...
found fd 6 mapped to socket 0 (127.0.0.1:8081)
running /usr/local/python3/bin/uwsgi
[uWSGI] getting INI configuration from uwsgi.ini
*** Starting uWSGI 2.0.18 (64bit) on [Wed Oct 23 20:33:25 2019] ***
compiled with version: 4.8.5 20150623 (Red Hat 4.8.5-39) on 21 October 2019 12:48:53
os: Linux-3.10.0-957.21.3.el7.x86_64 #1 SMP Tue Jun 18 16:35:19 UTC 2019
nodename: VM_0_6_centos
machine: x86_64
clock source: unix
pcre jit disabled
detected number of CPU cores: 1
current working directory: /usr/local/webserver/FSS
detected binary path: /usr/local/python3/bin/uwsgi
uWSGI running as root, you can use --uid/--gid/--chroot options
*** WARNING: you are running uWSGI as root !!! (use the --uid flag) *** 
chdir() to /usr/local/webserver/FSS/
your processes number limit is 7269
your memory page size is 4096 bytes
detected max file descriptor number: 100001
lock engine: pthread robust mutexes
thunder lock: disabled (you can enable it with --thunder-lock)
uwsgi socket 0 inherited INET address 127.0.0.1:8081 fd 6
uWSGI running as root, you can use --uid/--gid/--chroot options
*** WARNING: you are running uWSGI as root !!! (use the --uid flag) *** 
Python version: 3.6.1 (default, Oct 19 2019, 16:14:38)  [GCC 4.8.5 20150623 (Red Hat 4.8.5-36)]
Python main interpreter initialized at 0x23b6f40
uWSGI running as root, you can use --uid/--gid/--chroot options
*** WARNING: you are running uWSGI as root !!! (use the --uid flag) *** 
python threads support enabled
your server socket listen backlog is limited to 100 connections
your mercy for graceful operations on workers is 60 seconds
mapped 250128 bytes (244 KB) for 4 cores
*** Operational MODE: preforking+threaded ***
WSGI app 0 (mountpoint='') ready in 1 seconds on interpreter 0x23b6f40 pid: 9740 (default app)
uWSGI running as root, you can use --uid/--gid/--chroot options
*** WARNING: you are running uWSGI as root !!! (use the --uid flag) *** 
*** uWSGI is running in multiple interpreter mode ***
gracefully (RE)spawned uWSGI master process (pid: 9740)
spawned uWSGI worker 1 (pid: 10613, cores: 2)
spawned uWSGI worker 2 (pid: 10614, cores: 2)
[pid: 10613|app: 0|req: 1/1] 58.217.103.52 () {40 vars in 729 bytes} [Wed Oct 23 20:34:27 2019] GET /login/ => generated 192 bytes in 2 msecs (HTTP/1.1 400) 2 headers in 74 bytes (1 switches on core 0)
[pid: 10614|app: 0|req: 1/2] 58.217.103.52 () {40 vars in 674 bytes} [Wed Oct 23 20:34:27 2019] GET /favicon.ico => generated 232 bytes in 2 msecs (HTTP/1.1 404) 2 headers in 72 bytes (1 switches on core 0)
Wed Oct 23 20:40:09 2019 - *** /usr/local/webserver/FSS/ has been touched... grace them all !!! ***
...gracefully killing workers...
Gracefully killing worker 1 (pid: 10613)...
Gracefully killing worker 2 (pid: 10614)...
worker 1 buried after 1 seconds
worker 2 buried after 1 seconds
binary reloading uWSGI...
chdir() to /usr/local/webserver/FSS
closing all non-uwsgi socket fds > 2 (max_fd = 100001)...
found fd 6 mapped to socket 0 (127.0.0.1:8081)
running /usr/local/python3/bin/uwsgi
[uWSGI] getting INI configuration from uwsgi.ini
*** Starting uWSGI 2.0.18 (64bit) on [Wed Oct 23 20:40:10 2019] ***
compiled with version: 4.8.5 20150623 (Red Hat 4.8.5-39) on 21 October 2019 12:48:53
os: Linux-3.10.0-957.21.3.el7.x86_64 #1 SMP Tue Jun 18 16:35:19 UTC 2019
nodename: VM_0_6_centos
machine: x86_64
clock source: unix
pcre jit disabled
detected number of CPU cores: 1
current working directory: /usr/local/webserver/FSS
detected binary path: /usr/local/python3/bin/uwsgi
uWSGI running as root, you can use --uid/--gid/--chroot options
*** WARNING: you are running uWSGI as root !!! (use the --uid flag) *** 
chdir() to /usr/local/webserver/FSS/
your processes number limit is 7269
your memory page size is 4096 bytes
detected max file descriptor number: 100001
lock engine: pthread robust mutexes
thunder lock: disabled (you can enable it with --thunder-lock)
uwsgi socket 0 inherited INET address 127.0.0.1:8081 fd 6
uWSGI running as root, you can use --uid/--gid/--chroot options
*** WARNING: you are running uWSGI as root !!! (use the --uid flag) *** 
Python version: 3.6.1 (default, Oct 19 2019, 16:14:38)  [GCC 4.8.5 20150623 (Red Hat 4.8.5-36)]
Python main interpreter initialized at 0xdc7f40
uWSGI running as root, you can use --uid/--gid/--chroot options
*** WARNING: you are running uWSGI as root !!! (use the --uid flag) *** 
python threads support enabled
your server socket listen backlog is limited to 100 connections
your mercy for graceful operations on workers is 60 seconds
mapped 250128 bytes (244 KB) for 4 cores
*** Operational MODE: preforking+threaded ***
WSGI app 0 (mountpoint='') ready in 1 seconds on interpreter 0xdc7f40 pid: 9740 (default app)
uWSGI running as root, you can use --uid/--gid/--chroot options
*** WARNING: you are running uWSGI as root !!! (use the --uid flag) *** 
*** uWSGI is running in multiple interpreter mode ***
gracefully (RE)spawned uWSGI master process (pid: 9740)
spawned uWSGI worker 1 (pid: 11913, cores: 2)
spawned uWSGI worker 2 (pid: 11915, cores: 2)
[pid: 11915|app: 0|req: 1/1] 58.217.103.52 () {40 vars in 667 bytes} [Wed Oct 23 20:41:38 2019] GET / => generated 336 bytes in 9 msecs (HTTP/1.1 200) 2 headers in 80 bytes (1 switches on core 0)
[pid: 11915|app: 0|req: 2/2] 58.217.103.52 () {42 vars in 698 bytes} [Wed Oct 23 20:41:47 2019] GET / => generated 336 bytes in 0 msecs (HTTP/1.1 200) 2 headers in 80 bytes (1 switches on core 0)
未登录
[pid: 11915|app: 0|req: 3/3] 58.217.103.52 () {38 vars in 525 bytes} [Wed Oct 23 20:44:02 2019] POST /login/ => generated 85 bytes in 858 msecs (HTTP/1.1 200) 2 headers in 71 bytes (1 switches on core 0)
[2019-10-23 20:51:51,216] ERROR in app: Exception on /login/ [POST]
Traceback (most recent call last):
  File "/usr/local/python3/lib/python3.6/site-packages/urllib3/connection.py", line 157, in _new_conn
    (self._dns_host, self.port), self.timeout, **extra_kw
  File "/usr/local/python3/lib/python3.6/site-packages/urllib3/util/connection.py", line 84, in create_connection
    raise err
  File "/usr/local/python3/lib/python3.6/site-packages/urllib3/util/connection.py", line 74, in create_connection
    sock.connect(sa)
TimeoutError: [Errno 110] Connection timed out

During handling of the above exception, another exception occurred:

Traceback (most recent call last):
  File "/usr/local/python3/lib/python3.6/site-packages/urllib3/connectionpool.py", line 672, in urlopen
    chunked=chunked,
  File "/usr/local/python3/lib/python3.6/site-packages/urllib3/connectionpool.py", line 376, in _make_request
    self._validate_conn(conn)
  File "/usr/local/python3/lib/python3.6/site-packages/urllib3/connectionpool.py", line 994, in _validate_conn
    conn.connect()
  File "/usr/local/python3/lib/python3.6/site-packages/urllib3/connection.py", line 334, in connect
    conn = self._new_conn()
  File "/usr/local/python3/lib/python3.6/site-packages/urllib3/connection.py", line 169, in _new_conn
    self, "Failed to establish a new connection: %s" % e
urllib3.exceptions.NewConnectionError: <urllib3.connection.VerifiedHTTPSConnection object at 0x7f7740e90710>: Failed to establish a new connection: [Errno 110] Connection timed out

During handling of the above exception, another exception occurred:

Traceback (most recent call last):
  File "/usr/local/python3/lib/python3.6/site-packages/requests/adapters.py", line 449, in send
    timeout=timeout
  File "/usr/local/python3/lib/python3.6/site-packages/urllib3/connectionpool.py", line 720, in urlopen
    method, url, error=e, _pool=self, _stacktrace=sys.exc_info()[2]
  File "/usr/local/python3/lib/python3.6/site-packages/urllib3/util/retry.py", line 436, in increment
    raise MaxRetryError(_pool, url, error or ResponseError(cause))
urllib3.exceptions.MaxRetryError: HTTPSConnectionPool(host='vpn.just.edu.cn', port=443): Max retries exceeded with url: /dana-na/auth/url_default/login.cgi (Caused by NewConnectionError('<urllib3.connection.VerifiedHTTPSConnection object at 0x7f7740e90710>: Failed to establish a new connection: [Errno 110] Connection timed out',))

During handling of the above exception, another exception occurred:

Traceback (most recent call last):
  File "./VPN/vpnAccountManage.py", line 48, in vpn_account_or_useing
    link = session.post(url=url, data=vpn_data, cookies=cookies, headers=headers, verify=False)
  File "/usr/local/python3/lib/python3.6/site-packages/requests/sessions.py", line 581, in post
    return self.request('POST', url, data=data, json=json, **kwargs)
  File "/usr/local/python3/lib/python3.6/site-packages/requests/sessions.py", line 533, in request
    resp = self.send(prep, **send_kwargs)
  File "/usr/local/python3/lib/python3.6/site-packages/requests/sessions.py", line 646, in send
    r = adapter.send(request, **kwargs)
  File "/usr/local/python3/lib/python3.6/site-packages/requests/adapters.py", line 516, in send
    raise ConnectionError(e, request=request)
requests.exceptions.ConnectionError: HTTPSConnectionPool(host='vpn.just.edu.cn', port=443): Max retries exceeded with url: /dana-na/auth/url_default/login.cgi (Caused by NewConnectionError('<urllib3.connection.VerifiedHTTPSConnection object at 0x7f7740e90710>: Failed to establish a new connection: [Errno 110] Connection timed out',))

During handling of the above exception, another exception occurred:

Traceback (most recent call last):
  File "/usr/local/python3/lib/python3.6/site-packages/flask/app.py", line 2446, in wsgi_app
    response = self.full_dispatch_request()
  File "/usr/local/python3/lib/python3.6/site-packages/flask/app.py", line 1951, in full_dispatch_request
    rv = self.handle_user_exception(e)
  File "/usr/local/python3/lib/python3.6/site-packages/flask/app.py", line 1820, in handle_user_exception
    reraise(exc_type, exc_value, tb)
  File "/usr/local/python3/lib/python3.6/site-packages/flask/_compat.py", line 39, in reraise
    raise value
  File "/usr/local/python3/lib/python3.6/site-packages/flask/app.py", line 1949, in full_dispatch_request
    rv = self.dispatch_request()
  File "/usr/local/python3/lib/python3.6/site-packages/flask/app.py", line 1935, in dispatch_request
    return self.view_functions[rule.endpoint](**req.view_args)
  File "/usr/local/webserver/FSS/app.py", line 21, in login
    login_or_success, login_message = JL.login_vpn()
  File "./UserLogin/UserOperator.py", line 38, in login_vpn
    v_username, v_password = VA.get_can_use_account()
  File "./VPN/vpnAccountManage.py", line 87, in get_can_use_account
    stats = self.vpn_account_or_useing(username, password)
  File "./VPN/vpnAccountManage.py", line 50, in vpn_account_or_useing
    raise Exception('连接失败:{}'.format(e))
Exception: 连接失败:HTTPSConnectionPool(host='vpn.just.edu.cn', port=443): Max retries exceeded with url: /dana-na/auth/url_default/login.cgi (Caused by NewConnectionError('<urllib3.connection.VerifiedHTTPSConnection object at 0x7f7740e90710>: Failed to establish a new connection: [Errno 110] Connection timed out',))
[pid: 11915|app: 0|req: 5/4] 223.104.145.33 () {38 vars in 527 bytes} [Wed Oct 23 20:49:43 2019] POST /login/ => generated 290 bytes in 127272 msecs (HTTP/1.1 500) 2 headers in 84 bytes (1 switches on core 1)
未登录
[pid: 11915|app: 0|req: 6/5] 223.104.145.33 () {38 vars in 527 bytes} [Wed Oct 23 20:51:51 2019] POST /login/ => generated 85 bytes in 984 msecs (HTTP/1.1 200) 2 headers in 71 bytes (1 switches on core 1)
未登录
[pid: 11915|app: 0|req: 7/6] 223.104.145.33 () {38 vars in 527 bytes} [Wed Oct 23 20:51:52 2019] POST /login/ => generated 85 bytes in 1077 msecs (HTTP/1.1 200) 2 headers in 71 bytes (1 switches on core 1)
已登录
[pid: 11915|app: 0|req: 8/7] 223.104.145.33 () {38 vars in 527 bytes} [Wed Oct 23 20:51:53 2019] POST /login/ => generated 85 bytes in 1300 msecs (HTTP/1.1 200) 2 headers in 71 bytes (1 switches on core 1)
已登录
[pid: 11915|app: 0|req: 9/8] 223.104.145.33 () {38 vars in 527 bytes} [Wed Oct 23 20:51:54 2019] POST /login/ => generated 85 bytes in 973 msecs (HTTP/1.1 200) 2 headers in 71 bytes (1 switches on core 1)
未登录
[pid: 11915|app: 0|req: 10/9] 223.104.145.33 () {38 vars in 527 bytes} [Wed Oct 23 20:51:55 2019] POST /login/ => generated 85 bytes in 1632 msecs (HTTP/1.1 200) 2 headers in 71 bytes (1 switches on core 1)
未登录
[pid: 11915|app: 0|req: 11/10] 223.104.145.33 () {38 vars in 527 bytes} [Wed Oct 23 20:51:57 2019] POST /login/ => generated 85 bytes in 710 msecs (HTTP/1.1 200) 2 headers in 71 bytes (1 switches on core 1)
未登录
[2019-10-23 20:51:58,639] ERROR in app: Exception on /login/ [POST]
Traceback (most recent call last):
  File "/usr/local/python3/lib/python3.6/site-packages/urllib3/connection.py", line 157, in _new_conn
    (self._dns_host, self.port), self.timeout, **extra_kw
  File "/usr/local/python3/lib/python3.6/site-packages/urllib3/util/connection.py", line 84, in create_connection
    raise err
  File "/usr/local/python3/lib/python3.6/site-packages/urllib3/util/connection.py", line 74, in create_connection
    sock.connect(sa)
TimeoutError: [Errno 110] Connection timed out

During handling of the above exception, another exception occurred:

Traceback (most recent call last):
  File "/usr/local/python3/lib/python3.6/site-packages/urllib3/connectionpool.py", line 672, in urlopen
    chunked=chunked,
  File "/usr/local/python3/lib/python3.6/site-packages/urllib3/connectionpool.py", line 376, in _make_request
    self._validate_conn(conn)
  File "/usr/local/python3/lib/python3.6/site-packages/urllib3/connectionpool.py", line 994, in _validate_conn
    conn.connect()
  File "/usr/local/python3/lib/python3.6/site-packages/urllib3/connection.py", line 334, in connect
    conn = self._new_conn()
  File "/usr/local/python3/lib/python3.6/site-packages/urllib3/connection.py", line 169, in _new_conn
    self, "Failed to establish a new connection: %s" % e
urllib3.exceptions.NewConnectionError: <urllib3.connection.VerifiedHTTPSConnection object at 0x7f7740e9a7b8>: Failed to establish a new connection: [Errno 110] Connection timed out

During handling of the above exception, another exception occurred:

Traceback (most recent call last):
  File "/usr/local/python3/lib/python3.6/site-packages/requests/adapters.py", line 449, in send
    timeout=timeout
  File "/usr/local/python3/lib/python3.6/site-packages/urllib3/connectionpool.py", line 720, in urlopen
    method, url, error=e, _pool=self, _stacktrace=sys.exc_info()[2]
  File "/usr/local/python3/lib/python3.6/site-packages/urllib3/util/retry.py", line 436, in increment
    raise MaxRetryError(_pool, url, error or ResponseError(cause))
urllib3.exceptions.MaxRetryError: HTTPSConnectionPool(host='vpn.just.edu.cn', port=443): Max retries exceeded with url: /dana-na/auth/url_default/login.cgi (Caused by NewConnectionError('<urllib3.connection.VerifiedHTTPSConnection object at 0x7f7740e9a7b8>: Failed to establish a new connection: [Errno 110] Connection timed out',))

During handling of the above exception, another exception occurred:

Traceback (most recent call last):
  File "./VPN/vpnAccountManage.py", line 48, in vpn_account_or_useing
    link = session.post(url=url, data=vpn_data, cookies=cookies, headers=headers, verify=False)
  File "/usr/local/python3/lib/python3.6/site-packages/requests/sessions.py", line 581, in post
    return self.request('POST', url, data=data, json=json, **kwargs)
  File "/usr/local/python3/lib/python3.6/site-packages/requests/sessions.py", line 533, in request
    resp = self.send(prep, **send_kwargs)
  File "/usr/local/python3/lib/python3.6/site-packages/requests/sessions.py", line 646, in send
    r = adapter.send(request, **kwargs)
  File "/usr/local/python3/lib/python3.6/site-packages/requests/adapters.py", line 516, in send
    raise ConnectionError(e, request=request)
requests.exceptions.ConnectionError: HTTPSConnectionPool(host='vpn.just.edu.cn', port=443): Max retries exceeded with url: /dana-na/auth/url_default/login.cgi (Caused by NewConnectionError('<urllib3.connection.VerifiedHTTPSConnection object at 0x7f7740e9a7b8>: Failed to establish a new connection: [Errno 110] Connection timed out',))

During handling of the above exception, another exception occurred:

Traceback (most recent call last):
  File "/usr/local/python3/lib/python3.6/site-packages/flask/app.py", line 2446, in wsgi_app
    response = self.full_dispatch_request()
  File "/usr/local/python3/lib/python3.6/site-packages/flask/app.py", line 1951, in full_dispatch_request
    rv = self.handle_user_exception(e)
  File "/usr/local/python3/lib/python3.6/site-packages/flask/app.py", line 1820, in handle_user_exception
    reraise(exc_type, exc_value, tb)
  File "/usr/local/python3/lib/python3.6/site-packages/flask/_compat.py", line 39, in reraise
    raise value
  File "/usr/local/python3/lib/python3.6/site-packages/flask/app.py", line 1949, in full_dispatch_request
    rv = self.dispatch_request()
  File "/usr/local/python3/lib/python3.6/site-packages/flask/app.py", line 1935, in dispatch_request
    return self.view_functions[rule.endpoint](**req.view_args)
  File "/usr/local/webserver/FSS/app.py", line 21, in login
    login_or_success, login_message = JL.login_vpn()
  File "./UserLogin/UserOperator.py", line 38, in login_vpn
    v_username, v_password = VA.get_can_use_account()
  File "./VPN/vpnAccountManage.py", line 87, in get_can_use_account
    stats = self.vpn_account_or_useing(username, password)
  File "./VPN/vpnAccountManage.py", line 50, in vpn_account_or_useing
    raise Exception('连接失败:{}'.format(e))
Exception: 连接失败:HTTPSConnectionPool(host='vpn.just.edu.cn', port=443): Max retries exceeded with url: /dana-na/auth/url_default/login.cgi (Caused by NewConnectionError('<urllib3.connection.VerifiedHTTPSConnection object at 0x7f7740e9a7b8>: Failed to establish a new connection: [Errno 110] Connection timed out',))
[pid: 11915|app: 0|req: 12/11] 223.104.145.33 () {38 vars in 527 bytes} [Wed Oct 23 20:49:51 2019] POST /login/ => generated 290 bytes in 127415 msecs (HTTP/1.1 500) 2 headers in 84 bytes (1 switches on core 0)
[pid: 11915|app: 0|req: 13/12] 223.104.145.33 () {38 vars in 527 bytes} [Wed Oct 23 20:51:57 2019] POST /login/ => generated 85 bytes in 834 msecs (HTTP/1.1 200) 2 headers in 71 bytes (1 switches on core 1)
已登录
[pid: 11915|app: 0|req: 14/13] 223.104.145.33 () {38 vars in 527 bytes} [Wed Oct 23 20:51:58 2019] POST /login/ => generated 85 bytes in 994 msecs (HTTP/1.1 200) 2 headers in 71 bytes (1 switches on core 0)
未登录
未登录
[pid: 11915|app: 0|req: 15/14] 223.104.145.33 () {38 vars in 527 bytes} [Wed Oct 23 20:51:59 2019] POST /login/ => generated 85 bytes in 669 msecs (HTTP/1.1 200) 2 headers in 71 bytes (1 switches on core 0)
[pid: 11915|app: 0|req: 16/15] 223.104.145.33 () {38 vars in 527 bytes} [Wed Oct 23 20:51:58 2019] POST /login/ => generated 85 bytes in 1704 msecs (HTTP/1.1 200) 2 headers in 71 bytes (1 switches on core 1)
[2019-10-23 20:52:00,439] ERROR in app: Exception on /login/ [POST]
Traceback (most recent call last):
  File "/usr/local/python3/lib/python3.6/site-packages/urllib3/connection.py", line 157, in _new_conn
    (self._dns_host, self.port), self.timeout, **extra_kw
  File "/usr/local/python3/lib/python3.6/site-packages/urllib3/util/connection.py", line 84, in create_connection
    raise err
  File "/usr/local/python3/lib/python3.6/site-packages/urllib3/util/connection.py", line 74, in create_connection
    sock.connect(sa)
TimeoutError: [Errno 110] Connection timed out

During handling of the above exception, another exception occurred:

Traceback (most recent call last):
  File "/usr/local/python3/lib/python3.6/site-packages/urllib3/connectionpool.py", line 672, in urlopen
    chunked=chunked,
  File "/usr/local/python3/lib/python3.6/site-packages/urllib3/connectionpool.py", line 376, in _make_request
    self._validate_conn(conn)
  File "/usr/local/python3/lib/python3.6/site-packages/urllib3/connectionpool.py", line 994, in _validate_conn
    conn.connect()
  File "/usr/local/python3/lib/python3.6/site-packages/urllib3/connection.py", line 334, in connect
    conn = self._new_conn()
  File "/usr/local/python3/lib/python3.6/site-packages/urllib3/connection.py", line 169, in _new_conn
    self, "Failed to establish a new connection: %s" % e
urllib3.exceptions.NewConnectionError: <urllib3.connection.VerifiedHTTPSConnection object at 0x7f7744a871d0>: Failed to establish a new connection: [Errno 110] Connection timed out

During handling of the above exception, another exception occurred:

Traceback (most recent call last):
  File "/usr/local/python3/lib/python3.6/site-packages/requests/adapters.py", line 449, in send
    timeout=timeout
  File "/usr/local/python3/lib/python3.6/site-packages/urllib3/connectionpool.py", line 720, in urlopen
    method, url, error=e, _pool=self, _stacktrace=sys.exc_info()[2]
  File "/usr/local/python3/lib/python3.6/site-packages/urllib3/util/retry.py", line 436, in increment
    raise MaxRetryError(_pool, url, error or ResponseError(cause))
urllib3.exceptions.MaxRetryError: HTTPSConnectionPool(host='vpn.just.edu.cn', port=443): Max retries exceeded with url: /dana-na/auth/url_default/login.cgi (Caused by NewConnectionError('<urllib3.connection.VerifiedHTTPSConnection object at 0x7f7744a871d0>: Failed to establish a new connection: [Errno 110] Connection timed out',))

During handling of the above exception, another exception occurred:

Traceback (most recent call last):
  File "./VPN/vpnAccountManage.py", line 48, in vpn_account_or_useing
    link = session.post(url=url, data=vpn_data, cookies=cookies, headers=headers, verify=False)
  File "/usr/local/python3/lib/python3.6/site-packages/requests/sessions.py", line 581, in post
    return self.request('POST', url, data=data, json=json, **kwargs)
  File "/usr/local/python3/lib/python3.6/site-packages/requests/sessions.py", line 533, in request
    resp = self.send(prep, **send_kwargs)
  File "/usr/local/python3/lib/python3.6/site-packages/requests/sessions.py", line 646, in send
    r = adapter.send(request, **kwargs)
  File "/usr/local/python3/lib/python3.6/site-packages/requests/adapters.py", line 516, in send
    raise ConnectionError(e, request=request)
requests.exceptions.ConnectionError: HTTPSConnectionPool(host='vpn.just.edu.cn', port=443): Max retries exceeded with url: /dana-na/auth/url_default/login.cgi (Caused by NewConnectionError('<urllib3.connection.VerifiedHTTPSConnection object at 0x7f7744a871d0>: Failed to establish a new connection: [Errno 110] Connection timed out',))

During handling of the above exception, another exception occurred:

Traceback (most recent call last):
  File "/usr/local/python3/lib/python3.6/site-packages/flask/app.py", line 2446, in wsgi_app
    response = self.full_dispatch_request()
  File "/usr/local/python3/lib/python3.6/site-packages/flask/app.py", line 1951, in full_dispatch_request
    rv = self.handle_user_exception(e)
  File "/usr/local/python3/lib/python3.6/site-packages/flask/app.py", line 1820, in handle_user_exception
    reraise(exc_type, exc_value, tb)
  File "/usr/local/python3/lib/python3.6/site-packages/flask/_compat.py", line 39, in reraise
    raise value
  File "/usr/local/python3/lib/python3.6/site-packages/flask/app.py", line 1949, in full_dispatch_request
    rv = self.dispatch_request()
  File "/usr/local/python3/lib/python3.6/site-packages/flask/app.py", line 1935, in dispatch_request
    return self.view_functions[rule.endpoint](**req.view_args)
  File "/usr/local/webserver/FSS/app.py", line 21, in login
    login_or_success, login_message = JL.login_vpn()
  File "./UserLogin/UserOperator.py", line 38, in login_vpn
    v_username, v_password = VA.get_can_use_account()
  File "./VPN/vpnAccountManage.py", line 87, in get_can_use_account
    stats = self.vpn_account_or_useing(username, password)
  File "./VPN/vpnAccountManage.py", line 50, in vpn_account_or_useing
    raise Exception('连接失败:{}'.format(e))
Exception: 连接失败:HTTPSConnectionPool(host='vpn.just.edu.cn', port=443): Max retries exceeded with url: /dana-na/auth/url_default/login.cgi (Caused by NewConnectionError('<urllib3.connection.VerifiedHTTPSConnection object at 0x7f7744a871d0>: Failed to establish a new connection: [Errno 110] Connection timed out',))
[pid: 11913|app: 0|req: 2/16] 223.104.145.33 () {38 vars in 527 bytes} [Wed Oct 23 20:49:53 2019] POST /login/ => generated 290 bytes in 127297 msecs (HTTP/1.1 500) 2 headers in 84 bytes (1 switches on core 0)
[2019-10-23 20:52:00,815] ERROR in app: Exception on /login/ [POST]
Traceback (most recent call last):
  File "/usr/local/python3/lib/python3.6/site-packages/urllib3/connection.py", line 157, in _new_conn
    (self._dns_host, self.port), self.timeout, **extra_kw
  File "/usr/local/python3/lib/python3.6/site-packages/urllib3/util/connection.py", line 84, in create_connection
    raise err
  File "/usr/local/python3/lib/python3.6/site-packages/urllib3/util/connection.py", line 74, in create_connection
    sock.connect(sa)
TimeoutError: [Errno 110] Connection timed out

During handling of the above exception, another exception occurred:

Traceback (most recent call last):
  File "/usr/local/python3/lib/python3.6/site-packages/urllib3/connectionpool.py", line 672, in urlopen
    chunked=chunked,
  File "/usr/local/python3/lib/python3.6/site-packages/urllib3/connectionpool.py", line 376, in _make_request
    self._validate_conn(conn)
  File "/usr/local/python3/lib/python3.6/site-packages/urllib3/connectionpool.py", line 994, in _validate_conn
    conn.connect()
  File "/usr/local/python3/lib/python3.6/site-packages/urllib3/connection.py", line 334, in connect
    conn = self._new_conn()
  File "/usr/local/python3/lib/python3.6/site-packages/urllib3/connection.py", line 169, in _new_conn
    self, "Failed to establish a new connection: %s" % e
urllib3.exceptions.NewConnectionError: <urllib3.connection.VerifiedHTTPSConnection object at 0x7f77419c9438>: Failed to establish a new connection: [Errno 110] Connection timed out

During handling of the above exception, another exception occurred:

Traceback (most recent call last):
  File "/usr/local/python3/lib/python3.6/site-packages/requests/adapters.py", line 449, in send
    timeout=timeout
  File "/usr/local/python3/lib/python3.6/site-packages/urllib3/connectionpool.py", line 720, in urlopen
    method, url, error=e, _pool=self, _stacktrace=sys.exc_info()[2]
  File "/usr/local/python3/lib/python3.6/site-packages/urllib3/util/retry.py", line 436, in increment
    raise MaxRetryError(_pool, url, error or ResponseError(cause))
urllib3.exceptions.MaxRetryError: HTTPSConnectionPool(host='vpn.just.edu.cn', port=443): Max retries exceeded with url: /dana-na/auth/url_default/login.cgi (Caused by NewConnectionError('<urllib3.connection.VerifiedHTTPSConnection object at 0x7f77419c9438>: Failed to establish a new connection: [Errno 110] Connection timed out',))

During handling of the above exception, another exception occurred:

Traceback (most recent call last):
  File "./VPN/vpnAccountManage.py", line 48, in vpn_account_or_useing
    link = session.post(url=url, data=vpn_data, cookies=cookies, headers=headers, verify=False)
  File "/usr/local/python3/lib/python3.6/site-packages/requests/sessions.py", line 581, in post
    return self.request('POST', url, data=data, json=json, **kwargs)
  File "/usr/local/python3/lib/python3.6/site-packages/requests/sessions.py", line 533, in request
    resp = self.send(prep, **send_kwargs)
  File "/usr/local/python3/lib/python3.6/site-packages/requests/sessions.py", line 646, in send
    r = adapter.send(request, **kwargs)
  File "/usr/local/python3/lib/python3.6/site-packages/requests/adapters.py", line 516, in send
    raise ConnectionError(e, request=request)
requests.exceptions.ConnectionError: HTTPSConnectionPool(host='vpn.just.edu.cn', port=443): Max retries exceeded with url: /dana-na/auth/url_default/login.cgi (Caused by NewConnectionError('<urllib3.connection.VerifiedHTTPSConnection object at 0x7f77419c9438>: Failed to establish a new connection: [Errno 110] Connection timed out',))

During handling of the above exception, another exception occurred:

Traceback (most recent call last):
  File "/usr/local/python3/lib/python3.6/site-packages/flask/app.py", line 2446, in wsgi_app
    response = self.full_dispatch_request()
  File "/usr/local/python3/lib/python3.6/site-packages/flask/app.py", line 1951, in full_dispatch_request
    rv = self.handle_user_exception(e)
  File "/usr/local/python3/lib/python3.6/site-packages/flask/app.py", line 1820, in handle_user_exception
    reraise(exc_type, exc_value, tb)
  File "/usr/local/python3/lib/python3.6/site-packages/flask/_compat.py", line 39, in reraise
    raise value
  File "/usr/local/python3/lib/python3.6/site-packages/flask/app.py", line 1949, in full_dispatch_request
    rv = self.dispatch_request()
  File "/usr/local/python3/lib/python3.6/site-packages/flask/app.py", line 1935, in dispatch_request
    return self.view_functions[rule.endpoint](**req.view_args)
  File "/usr/local/webserver/FSS/app.py", line 21, in login
    login_or_success, login_message = JL.login_vpn()
  File "./UserLogin/UserOperator.py", line 38, in login_vpn
    v_username, v_password = VA.get_can_use_account()
  File "./VPN/vpnAccountManage.py", line 87, in get_can_use_account
    stats = self.vpn_account_or_useing(username, password)
  File "./VPN/vpnAccountManage.py", line 50, in vpn_account_or_useing
    raise Exception('连接失败:{}'.format(e))
Exception: 连接失败:HTTPSConnectionPool(host='vpn.just.edu.cn', port=443): Max retries exceeded with url: /dana-na/auth/url_default/login.cgi (Caused by NewConnectionError('<urllib3.connection.VerifiedHTTPSConnection object at 0x7f77419c9438>: Failed to establish a new connection: [Errno 110] Connection timed out',))
[pid: 11913|app: 0|req: 3/17] 223.104.145.33 () {38 vars in 527 bytes} [Wed Oct 23 20:49:53 2019] POST /login/ => generated 290 bytes in 127333 msecs (HTTP/1.1 500) 2 headers in 84 bytes (1 switches on core 1)
未登录
[pid: 11915|app: 0|req: 17/18] 223.104.145.33 () {38 vars in 527 bytes} [Wed Oct 23 20:52:00 2019] POST /login/ => generated 85 bytes in 882 msecs (HTTP/1.1 200) 2 headers in 71 bytes (1 switches on core 0)
已登录
[pid: 11915|app: 0|req: 18/19] 223.104.145.33 () {38 vars in 527 bytes} [Wed Oct 23 20:52:00 2019] POST /login/ => generated 85 bytes in 1038 msecs (HTTP/1.1 200) 2 headers in 71 bytes (1 switches on core 1)
已登录
未登录
[pid: 11915|app: 0|req: 19/20] 223.104.145.33 () {38 vars in 527 bytes} [Wed Oct 23 20:52:01 2019] POST /login/ => generated 85 bytes in 889 msecs (HTTP/1.1 200) 2 headers in 71 bytes (1 switches on core 0)
未登录
未登录
[2019-10-23 20:52:02,408] ERROR in app: Exception on /login/ [POST]
Traceback (most recent call last):
  File "./UserLogin/UserOperator.py", line 88, in find_userInfo
    text = BS.find('div', attrs={'id': 'Top1_divLoginName'}).text
AttributeError: 'NoneType' object has no attribute 'text'

During handling of the above exception, another exception occurred:

Traceback (most recent call last):
  File "/usr/local/python3/lib/python3.6/site-packages/flask/app.py", line 2446, in wsgi_app
    response = self.full_dispatch_request()
  File "/usr/local/python3/lib/python3.6/site-packages/flask/app.py", line 1951, in full_dispatch_request
    rv = self.handle_user_exception(e)
  File "/usr/local/python3/lib/python3.6/site-packages/flask/app.py", line 1820, in handle_user_exception
    reraise(exc_type, exc_value, tb)
  File "/usr/local/python3/lib/python3.6/site-packages/flask/_compat.py", line 39, in reraise
    raise value
  File "/usr/local/python3/lib/python3.6/site-packages/flask/app.py", line 1949, in full_dispatch_request
    rv = self.dispatch_request()
  File "/usr/local/python3/lib/python3.6/site-packages/flask/app.py", line 1935, in dispatch_request
    return self.view_functions[rule.endpoint](**req.view_args)
  File "/usr/local/webserver/FSS/app.py", line 24, in login
    'username': JL.find_userInfo(),
  File "./UserLogin/UserOperator.py", line 90, in find_userInfo
    raise Exception("获取失败")
Exception: 获取失败
[pid: 11913|app: 0|req: 4/21] 223.104.145.33 () {38 vars in 527 bytes} [Wed Oct 23 20:52:00 2019] POST /login/ => generated 290 bytes in 1593 msecs (HTTP/1.1 500) 2 headers in 84 bytes (1 switches on core 1)
[pid: 11915|app: 0|req: 20/22] 223.104.145.33 () {38 vars in 527 bytes} [Wed Oct 23 20:52:01 2019] POST /login/ => generated 85 bytes in 1019 msecs (HTTP/1.1 200) 2 headers in 71 bytes (1 switches on core 1)
[pid: 11913|app: 0|req: 5/23] 223.104.145.33 () {38 vars in 527 bytes} [Wed Oct 23 20:52:00 2019] POST /login/ => generated 85 bytes in 2119 msecs (HTTP/1.1 200) 2 headers in 71 bytes (1 switches on core 0)
已登录
已登录
已登录
已登录
[2019-10-23 20:52:03,399] ERROR in app: Exception on /login/ [POST]
Traceback (most recent call last):
  File "./UserLogin/UserOperator.py", line 88, in find_userInfo
    text = BS.find('div', attrs={'id': 'Top1_divLoginName'}).text
AttributeError: 'NoneType' object has no attribute 'text'

During handling of the above exception, another exception occurred:

Traceback (most recent call last):
  File "/usr/local/python3/lib/python3.6/site-packages/flask/app.py", line 2446, in wsgi_app
    response = self.full_dispatch_request()
  File "/usr/local/python3/lib/python3.6/site-packages/flask/app.py", line 1951, in full_dispatch_request
    rv = self.handle_user_exception(e)
  File "/usr/local/python3/lib/python3.6/site-packages/flask/app.py", line 1820, in handle_user_exception
    reraise(exc_type, exc_value, tb)
  File "/usr/local/python3/lib/python3.6/site-packages/flask/_compat.py", line 39, in reraise
    raise value
  File "/usr/local/python3/lib/python3.6/site-packages/flask/app.py", line 1949, in full_dispatch_request
    rv = self.dispatch_request()
  File "/usr/local/python3/lib/python3.6/site-packages/flask/app.py", line 1935, in dispatch_request
    return self.view_functions[rule.endpoint](**req.view_args)
  File "/usr/local/webserver/FSS/app.py", line 24, in login
    'username': JL.find_userInfo(),
  File "./UserLogin/UserOperator.py", line 90, in find_userInfo
    raise Exception("获取失败")
Exception: 获取失败
[pid: 11915|app: 0|req: 21/24] 223.104.145.33 () {38 vars in 527 bytes} [Wed Oct 23 20:52:02 2019] POST /login/ => generated 290 bytes in 1323 msecs (HTTP/1.1 500) 2 headers in 84 bytes (1 switches on core 0)
[2019-10-23 20:52:03,558] ERROR in app: Exception on /login/ [POST]
Traceback (most recent call last):
  File "./UserLogin/UserOperator.py", line 71, in login_vpn
    raise Exception('校园vpn连接失败')
Exception: 校园vpn连接失败

During handling of the above exception, another exception occurred:

Traceback (most recent call last):
  File "/usr/local/python3/lib/python3.6/site-packages/flask/app.py", line 2446, in wsgi_app
    response = self.full_dispatch_request()
  File "/usr/local/python3/lib/python3.6/site-packages/flask/app.py", line 1951, in full_dispatch_request
    rv = self.handle_user_exception(e)
  File "/usr/local/python3/lib/python3.6/site-packages/flask/app.py", line 1820, in handle_user_exception
    reraise(exc_type, exc_value, tb)
  File "/usr/local/python3/lib/python3.6/site-packages/flask/_compat.py", line 39, in reraise
    raise value
  File "/usr/local/python3/lib/python3.6/site-packages/flask/app.py", line 1949, in full_dispatch_request
    rv = self.dispatch_request()
  File "/usr/local/python3/lib/python3.6/site-packages/flask/app.py", line 1935, in dispatch_request
    return self.view_functions[rule.endpoint](**req.view_args)
  File "/usr/local/webserver/FSS/app.py", line 21, in login
    login_or_success, login_message = JL.login_vpn()
  File "./UserLogin/UserOperator.py", line 77, in login_vpn
    raise Exception("【】未知异常】:{}".format(e))
Exception: 【】未知异常】:校园vpn连接失败
[pid: 11915|app: 0|req: 22/25] 223.104.145.33 () {38 vars in 527 bytes} [Wed Oct 23 20:52:02 2019] POST /login/ => generated 290 bytes in 1063 msecs (HTTP/1.1 500) 2 headers in 84 bytes (1 switches on core 1)
[pid: 11913|app: 0|req: 6/26] 223.104.145.33 () {38 vars in 527 bytes} [Wed Oct 23 20:52:02 2019] POST /login/ => generated 85 bytes in 1059 msecs (HTTP/1.1 200) 2 headers in 71 bytes (1 switches on core 0)
[2019-10-23 20:52:03,763] ERROR in app: Exception on /login/ [POST]
Traceback (most recent call last):
  File "./UserLogin/UserOperator.py", line 88, in find_userInfo
    text = BS.find('div', attrs={'id': 'Top1_divLoginName'}).text
AttributeError: 'NoneType' object has no attribute 'text'

During handling of the above exception, another exception occurred:

Traceback (most recent call last):
  File "/usr/local/python3/lib/python3.6/site-packages/flask/app.py", line 2446, in wsgi_app
    response = self.full_dispatch_request()
  File "/usr/local/python3/lib/python3.6/site-packages/flask/app.py", line 1951, in full_dispatch_request
    rv = self.handle_user_exception(e)
  File "/usr/local/python3/lib/python3.6/site-packages/flask/app.py", line 1820, in handle_user_exception
    reraise(exc_type, exc_value, tb)
  File "/usr/local/python3/lib/python3.6/site-packages/flask/_compat.py", line 39, in reraise
    raise value
  File "/usr/local/python3/lib/python3.6/site-packages/flask/app.py", line 1949, in full_dispatch_request
    rv = self.dispatch_request()
  File "/usr/local/python3/lib/python3.6/site-packages/flask/app.py", line 1935, in dispatch_request
    return self.view_functions[rule.endpoint](**req.view_args)
  File "/usr/local/webserver/FSS/app.py", line 24, in login
    'username': JL.find_userInfo(),
  File "./UserLogin/UserOperator.py", line 90, in find_userInfo
    raise Exception("获取失败")
Exception: 获取失败
[pid: 11913|app: 0|req: 7/27] 223.104.145.33 () {38 vars in 527 bytes} [Wed Oct 23 20:52:02 2019] POST /login/ => generated 290 bytes in 1354 msecs (HTTP/1.1 500) 2 headers in 84 bytes (1 switches on core 1)
已登录
[pid: 11915|app: 0|req: 23/28] 223.104.145.33 () {38 vars in 527 bytes} [Wed Oct 23 20:52:03 2019] POST /login/ => generated 85 bytes in 949 msecs (HTTP/1.1 200) 2 headers in 71 bytes (1 switches on core 0)
已登录
已登录
已登录
[2019-10-23 20:52:04,772] ERROR in app: Exception on /login/ [POST]
Traceback (most recent call last):
  File "./UserLogin/UserOperator.py", line 71, in login_vpn
    raise Exception('校园vpn连接失败')
Exception: 校园vpn连接失败

During handling of the above exception, another exception occurred:

Traceback (most recent call last):
  File "/usr/local/python3/lib/python3.6/site-packages/flask/app.py", line 2446, in wsgi_app
    response = self.full_dispatch_request()
  File "/usr/local/python3/lib/python3.6/site-packages/flask/app.py", line 1951, in full_dispatch_request
    rv = self.handle_user_exception(e)
  File "/usr/local/python3/lib/python3.6/site-packages/flask/app.py", line 1820, in handle_user_exception
    reraise(exc_type, exc_value, tb)
  File "/usr/local/python3/lib/python3.6/site-packages/flask/_compat.py", line 39, in reraise
    raise value
  File "/usr/local/python3/lib/python3.6/site-packages/flask/app.py", line 1949, in full_dispatch_request
    rv = self.dispatch_request()
  File "/usr/local/python3/lib/python3.6/site-packages/flask/app.py", line 1935, in dispatch_request
    return self.view_functions[rule.endpoint](**req.view_args)
  File "/usr/local/webserver/FSS/app.py", line 21, in login
    login_or_success, login_message = JL.login_vpn()
  File "./UserLogin/UserOperator.py", line 77, in login_vpn
    raise Exception("【】未知异常】:{}".format(e))
Exception: 【】未知异常】:校园vpn连接失败
[pid: 11915|app: 0|req: 24/29] 223.104.145.33 () {38 vars in 527 bytes} [Wed Oct 23 20:52:03 2019] POST /login/ => generated 290 bytes in 1214 msecs (HTTP/1.1 500) 2 headers in 84 bytes (1 switches on core 1)
[pid: 11913|app: 0|req: 8/30] 223.104.145.33 () {38 vars in 527 bytes} [Wed Oct 23 20:52:03 2019] POST /login/ => generated 85 bytes in 1190 msecs (HTTP/1.1 200) 2 headers in 71 bytes (1 switches on core 1)
[2019-10-23 20:52:05,191] ERROR in app: Exception on /login/ [POST]
Traceback (most recent call last):
  File "./UserLogin/UserOperator.py", line 88, in find_userInfo
    text = BS.find('div', attrs={'id': 'Top1_divLoginName'}).text
AttributeError: 'NoneType' object has no attribute 'text'

During handling of the above exception, another exception occurred:

Traceback (most recent call last):
  File "/usr/local/python3/lib/python3.6/site-packages/flask/app.py", line 2446, in wsgi_app
    response = self.full_dispatch_request()
  File "/usr/local/python3/lib/python3.6/site-packages/flask/app.py", line 1951, in full_dispatch_request
    rv = self.handle_user_exception(e)
  File "/usr/local/python3/lib/python3.6/site-packages/flask/app.py", line 1820, in handle_user_exception
    reraise(exc_type, exc_value, tb)
  File "/usr/local/python3/lib/python3.6/site-packages/flask/_compat.py", line 39, in reraise
    raise value
  File "/usr/local/python3/lib/python3.6/site-packages/flask/app.py", line 1949, in full_dispatch_request
    rv = self.dispatch_request()
  File "/usr/local/python3/lib/python3.6/site-packages/flask/app.py", line 1935, in dispatch_request
    return self.view_functions[rule.endpoint](**req.view_args)
  File "/usr/local/webserver/FSS/app.py", line 24, in login
    'username': JL.find_userInfo(),
  File "./UserLogin/UserOperator.py", line 90, in find_userInfo
    raise Exception("获取失败")
Exception: 获取失败
[pid: 11913|app: 0|req: 9/31] 223.104.145.33 () {38 vars in 527 bytes} [Wed Oct 23 20:52:03 2019] POST /login/ => generated 290 bytes in 1570 msecs (HTTP/1.1 500) 2 headers in 84 bytes (1 switches on core 0)
已登录
[pid: 11915|app: 0|req: 25/32] 223.104.145.33 () {38 vars in 527 bytes} [Wed Oct 23 20:52:04 2019] POST /login/ => generated 85 bytes in 1289 msecs (HTTP/1.1 200) 2 headers in 71 bytes (1 switches on core 0)
已登录
已登录
未登录
[pid: 11915|app: 0|req: 26/33] 223.104.145.33 () {38 vars in 527 bytes} [Wed Oct 23 20:52:05 2019] POST /login/ => generated 85 bytes in 885 msecs (HTTP/1.1 200) 2 headers in 71 bytes (1 switches on core 0)
[2019-10-23 20:52:06,559] ERROR in app: Exception on /login/ [POST]
Traceback (most recent call last):
  File "./UserLogin/UserOperator.py", line 88, in find_userInfo
    text = BS.find('div', attrs={'id': 'Top1_divLoginName'}).text
AttributeError: 'NoneType' object has no attribute 'text'

During handling of the above exception, another exception occurred:

Traceback (most recent call last):
  File "/usr/local/python3/lib/python3.6/site-packages/flask/app.py", line 2446, in wsgi_app
    response = self.full_dispatch_request()
  File "/usr/local/python3/lib/python3.6/site-packages/flask/app.py", line 1951, in full_dispatch_request
    rv = self.handle_user_exception(e)
  File "/usr/local/python3/lib/python3.6/site-packages/flask/app.py", line 1820, in handle_user_exception
    reraise(exc_type, exc_value, tb)
  File "/usr/local/python3/lib/python3.6/site-packages/flask/_compat.py", line 39, in reraise
    raise value
  File "/usr/local/python3/lib/python3.6/site-packages/flask/app.py", line 1949, in full_dispatch_request
    rv = self.dispatch_request()
  File "/usr/local/python3/lib/python3.6/site-packages/flask/app.py", line 1935, in dispatch_request
    return self.view_functions[rule.endpoint](**req.view_args)
  File "/usr/local/webserver/FSS/app.py", line 24, in login
    'username': JL.find_userInfo(),
  File "./UserLogin/UserOperator.py", line 90, in find_userInfo
    raise Exception("获取失败")
Exception: 获取失败
[pid: 11913|app: 0|req: 10/34] 223.104.145.33 () {38 vars in 527 bytes} [Wed Oct 23 20:52:04 2019] POST /login/ => generated 290 bytes in 1604 msecs (HTTP/1.1 500) 2 headers in 84 bytes (1 switches on core 1)
未登录
[2019-10-23 20:52:06,724] ERROR in app: Exception on /login/ [POST]
Traceback (most recent call last):
  File "./UserLogin/UserOperator.py", line 88, in find_userInfo
    text = BS.find('div', attrs={'id': 'Top1_divLoginName'}).text
AttributeError: 'NoneType' object has no attribute 'text'

During handling of the above exception, another exception occurred:

Traceback (most recent call last):
  File "/usr/local/python3/lib/python3.6/site-packages/flask/app.py", line 2446, in wsgi_app
    response = self.full_dispatch_request()
  File "/usr/local/python3/lib/python3.6/site-packages/flask/app.py", line 1951, in full_dispatch_request
    rv = self.handle_user_exception(e)
  File "/usr/local/python3/lib/python3.6/site-packages/flask/app.py", line 1820, in handle_user_exception
    reraise(exc_type, exc_value, tb)
  File "/usr/local/python3/lib/python3.6/site-packages/flask/_compat.py", line 39, in reraise
    raise value
  File "/usr/local/python3/lib/python3.6/site-packages/flask/app.py", line 1949, in full_dispatch_request
    rv = self.dispatch_request()
  File "/usr/local/python3/lib/python3.6/site-packages/flask/app.py", line 1935, in dispatch_request
    return self.view_functions[rule.endpoint](**req.view_args)
  File "/usr/local/webserver/FSS/app.py", line 24, in login
    'username': JL.find_userInfo(),
  File "./UserLogin/UserOperator.py", line 90, in find_userInfo
    raise Exception("获取失败")
Exception: 获取失败
[pid: 11913|app: 0|req: 10/35] 223.104.145.33 () {38 vars in 527 bytes} [Wed Oct 23 20:52:05 2019] POST /login/ => generated 290 bytes in 1533 msecs (HTTP/1.1 500) 2 headers in 84 bytes (1 switches on core 0)
[pid: 11915|app: 0|req: 27/36] 223.104.145.33 () {38 vars in 527 bytes} [Wed Oct 23 20:52:04 2019] POST /login/ => generated 85 bytes in 2110 msecs (HTTP/1.1 200) 2 headers in 71 bytes (1 switches on core 1)
未登录
[pid: 11915|app: 0|req: 27/37] 223.104.145.33 () {38 vars in 527 bytes} [Wed Oct 23 20:52:06 2019] POST /login/ => generated 85 bytes in 789 msecs (HTTP/1.1 200) 2 headers in 71 bytes (1 switches on core 0)
[pid: 11915|app: 0|req: 28/38] 58.217.103.52 () {42 vars in 698 bytes} [Wed Oct 23 20:53:35 2019] GET / => generated 336 bytes in 0 msecs (HTTP/1.1 200) 2 headers in 80 bytes (1 switches on core 1)
[pid: 11915|app: 0|req: 29/39] 58.217.103.52 () {42 vars in 698 bytes} [Wed Oct 23 20:53:36 2019] GET / => generated 336 bytes in 0 msecs (HTTP/1.1 200) 2 headers in 80 bytes (1 switches on core 1)
[pid: 11913|app: 0|req: 11/40] 103.140.127.138 () {34 vars in 599 bytes} [Wed Oct 23 20:54:02 2019] GET /%73%65%65%79%6F%6E/%68%74%6D%6C%6F%66%66%69%63%65%73%65%72%76%6C%65%74 => generated 232 bytes in 0 msecs (HTTP/1.1 404) 2 headers in 72 bytes (1 switches on core 1)
[pid: 11913|app: 0|req: 12/41] 103.140.127.138 () {34 vars in 587 bytes} [Wed Oct 23 20:54:02 2019] GET /secure/ContactAdministrators!default.jspa => generated 232 bytes in 0 msecs (HTTP/1.1 404) 2 headers in 72 bytes (1 switches on core 1)
[pid: 11913|app: 0|req: 13/42] 103.140.127.138 () {34 vars in 477 bytes} [Wed Oct 23 20:54:02 2019] GET /manager/html => generated 232 bytes in 0 msecs (HTTP/1.1 404) 2 headers in 72 bytes (1 switches on core 1)
已登录
[pid: 11913|app: 0|req: 14/43] 58.217.103.52 () {38 vars in 526 bytes} [Wed Oct 23 20:54:56 2019] POST /login/ => generated 85 bytes in 1114 msecs (HTTP/1.1 200) 2 headers in 71 bytes (1 switches on core 1)
[2019-10-23 20:55:55,951] ERROR in app: Exception on /login/ [POST]
Traceback (most recent call last):
  File "/usr/local/python3/lib/python3.6/site-packages/urllib3/connection.py", line 157, in _new_conn
    (self._dns_host, self.port), self.timeout, **extra_kw
  File "/usr/local/python3/lib/python3.6/site-packages/urllib3/util/connection.py", line 84, in create_connection
    raise err
  File "/usr/local/python3/lib/python3.6/site-packages/urllib3/util/connection.py", line 74, in create_connection
    sock.connect(sa)
TimeoutError: [Errno 110] Connection timed out

During handling of the above exception, another exception occurred:

Traceback (most recent call last):
  File "/usr/local/python3/lib/python3.6/site-packages/urllib3/connectionpool.py", line 672, in urlopen
    chunked=chunked,
  File "/usr/local/python3/lib/python3.6/site-packages/urllib3/connectionpool.py", line 376, in _make_request
    self._validate_conn(conn)
  File "/usr/local/python3/lib/python3.6/site-packages/urllib3/connectionpool.py", line 994, in _validate_conn
    conn.connect()
  File "/usr/local/python3/lib/python3.6/site-packages/urllib3/connection.py", line 334, in connect
    conn = self._new_conn()
  File "/usr/local/python3/lib/python3.6/site-packages/urllib3/connection.py", line 169, in _new_conn
    self, "Failed to establish a new connection: %s" % e
urllib3.exceptions.NewConnectionError: <urllib3.connection.VerifiedHTTPSConnection object at 0x7f7740e3b7f0>: Failed to establish a new connection: [Errno 110] Connection timed out

During handling of the above exception, another exception occurred:

Traceback (most recent call last):
  File "/usr/local/python3/lib/python3.6/site-packages/requests/adapters.py", line 449, in send
    timeout=timeout
  File "/usr/local/python3/lib/python3.6/site-packages/urllib3/connectionpool.py", line 720, in urlopen
    method, url, error=e, _pool=self, _stacktrace=sys.exc_info()[2]
  File "/usr/local/python3/lib/python3.6/site-packages/urllib3/util/retry.py", line 436, in increment
    raise MaxRetryError(_pool, url, error or ResponseError(cause))
urllib3.exceptions.MaxRetryError: HTTPSConnectionPool(host='vpn.just.edu.cn', port=443): Max retries exceeded with url: /dana-na/auth/url_default/login.cgi (Caused by NewConnectionError('<urllib3.connection.VerifiedHTTPSConnection object at 0x7f7740e3b7f0>: Failed to establish a new connection: [Errno 110] Connection timed out',))

During handling of the above exception, another exception occurred:

Traceback (most recent call last):
  File "./VPN/vpnAccountManage.py", line 48, in vpn_account_or_useing
    link = session.post(url=url, data=vpn_data, cookies=cookies, headers=headers, verify=False)
  File "/usr/local/python3/lib/python3.6/site-packages/requests/sessions.py", line 581, in post
    return self.request('POST', url, data=data, json=json, **kwargs)
  File "/usr/local/python3/lib/python3.6/site-packages/requests/sessions.py", line 533, in request
    resp = self.send(prep, **send_kwargs)
  File "/usr/local/python3/lib/python3.6/site-packages/requests/sessions.py", line 646, in send
    r = adapter.send(request, **kwargs)
  File "/usr/local/python3/lib/python3.6/site-packages/requests/adapters.py", line 516, in send
    raise ConnectionError(e, request=request)
requests.exceptions.ConnectionError: HTTPSConnectionPool(host='vpn.just.edu.cn', port=443): Max retries exceeded with url: /dana-na/auth/url_default/login.cgi (Caused by NewConnectionError('<urllib3.connection.VerifiedHTTPSConnection object at 0x7f7740e3b7f0>: Failed to establish a new connection: [Errno 110] Connection timed out',))

During handling of the above exception, another exception occurred:

Traceback (most recent call last):
  File "/usr/local/python3/lib/python3.6/site-packages/flask/app.py", line 2446, in wsgi_app
    response = self.full_dispatch_request()
  File "/usr/local/python3/lib/python3.6/site-packages/flask/app.py", line 1951, in full_dispatch_request
    rv = self.handle_user_exception(e)
  File "/usr/local/python3/lib/python3.6/site-packages/flask/app.py", line 1820, in handle_user_exception
    reraise(exc_type, exc_value, tb)
  File "/usr/local/python3/lib/python3.6/site-packages/flask/_compat.py", line 39, in reraise
    raise value
  File "/usr/local/python3/lib/python3.6/site-packages/flask/app.py", line 1949, in full_dispatch_request
    rv = self.dispatch_request()
  File "/usr/local/python3/lib/python3.6/site-packages/flask/app.py", line 1935, in dispatch_request
    return self.view_functions[rule.endpoint](**req.view_args)
  File "/usr/local/webserver/FSS/app.py", line 21, in login
    login_or_success, login_message = JL.login_vpn()
  File "./UserLogin/UserOperator.py", line 38, in login_vpn
    v_username, v_password = VA.get_can_use_account()
  File "./VPN/vpnAccountManage.py", line 87, in get_can_use_account
    stats = self.vpn_account_or_useing(username, password)
  File "./VPN/vpnAccountManage.py", line 50, in vpn_account_or_useing
    raise Exception('连接失败:{}'.format(e))
Exception: 连接失败:HTTPSConnectionPool(host='vpn.just.edu.cn', port=443): Max retries exceeded with url: /dana-na/auth/url_default/login.cgi (Caused by NewConnectionError('<urllib3.connection.VerifiedHTTPSConnection object at 0x7f7740e3b7f0>: Failed to establish a new connection: [Errno 110] Connection timed out',))
[pid: 11915|app: 0|req: 31/44] 58.217.103.52 () {38 vars in 526 bytes} [Wed Oct 23 20:53:48 2019] POST /login/ => generated 290 bytes in 127335 msecs (HTTP/1.1 500) 2 headers in 84 bytes (1 switches on core 1)
[2019-10-23 20:56:03,375] ERROR in app: Exception on /login/ [POST]
Traceback (most recent call last):
  File "/usr/local/python3/lib/python3.6/site-packages/urllib3/connection.py", line 157, in _new_conn
    (self._dns_host, self.port), self.timeout, **extra_kw
  File "/usr/local/python3/lib/python3.6/site-packages/urllib3/util/connection.py", line 84, in create_connection
    raise err
  File "/usr/local/python3/lib/python3.6/site-packages/urllib3/util/connection.py", line 74, in create_connection
    sock.connect(sa)
TimeoutError: [Errno 110] Connection timed out

During handling of the above exception, another exception occurred:

Traceback (most recent call last):
  File "/usr/local/python3/lib/python3.6/site-packages/urllib3/connectionpool.py", line 672, in urlopen
    chunked=chunked,
  File "/usr/local/python3/lib/python3.6/site-packages/urllib3/connectionpool.py", line 376, in _make_request
    self._validate_conn(conn)
  File "/usr/local/python3/lib/python3.6/site-packages/urllib3/connectionpool.py", line 994, in _validate_conn
    conn.connect()
  File "/usr/local/python3/lib/python3.6/site-packages/urllib3/connection.py", line 334, in connect
    conn = self._new_conn()
  File "/usr/local/python3/lib/python3.6/site-packages/urllib3/connection.py", line 169, in _new_conn
    self, "Failed to establish a new connection: %s" % e
urllib3.exceptions.NewConnectionError: <urllib3.connection.VerifiedHTTPSConnection object at 0x7f7740e2f898>: Failed to establish a new connection: [Errno 110] Connection timed out

During handling of the above exception, another exception occurred:

Traceback (most recent call last):
  File "/usr/local/python3/lib/python3.6/site-packages/requests/adapters.py", line 449, in send
    timeout=timeout
  File "/usr/local/python3/lib/python3.6/site-packages/urllib3/connectionpool.py", line 720, in urlopen
    method, url, error=e, _pool=self, _stacktrace=sys.exc_info()[2]
  File "/usr/local/python3/lib/python3.6/site-packages/urllib3/util/retry.py", line 436, in increment
    raise MaxRetryError(_pool, url, error or ResponseError(cause))
urllib3.exceptions.MaxRetryError: HTTPSConnectionPool(host='vpn.just.edu.cn', port=443): Max retries exceeded with url: /dana-na/auth/url_default/login.cgi (Caused by NewConnectionError('<urllib3.connection.VerifiedHTTPSConnection object at 0x7f7740e2f898>: Failed to establish a new connection: [Errno 110] Connection timed out',))

During handling of the above exception, another exception occurred:

Traceback (most recent call last):
  File "./VPN/vpnAccountManage.py", line 48, in vpn_account_or_useing
    link = session.post(url=url, data=vpn_data, cookies=cookies, headers=headers, verify=False)
  File "/usr/local/python3/lib/python3.6/site-packages/requests/sessions.py", line 581, in post
    return self.request('POST', url, data=data, json=json, **kwargs)
  File "/usr/local/python3/lib/python3.6/site-packages/requests/sessions.py", line 533, in request
    resp = self.send(prep, **send_kwargs)
  File "/usr/local/python3/lib/python3.6/site-packages/requests/sessions.py", line 646, in send
    r = adapter.send(request, **kwargs)
  File "/usr/local/python3/lib/python3.6/site-packages/requests/adapters.py", line 516, in send
    raise ConnectionError(e, request=request)
requests.exceptions.ConnectionError: HTTPSConnectionPool(host='vpn.just.edu.cn', port=443): Max retries exceeded with url: /dana-na/auth/url_default/login.cgi (Caused by NewConnectionError('<urllib3.connection.VerifiedHTTPSConnection object at 0x7f7740e2f898>: Failed to establish a new connection: [Errno 110] Connection timed out',))

During handling of the above exception, another exception occurred:

Traceback (most recent call last):
  File "/usr/local/python3/lib/python3.6/site-packages/flask/app.py", line 2446, in wsgi_app
    response = self.full_dispatch_request()
  File "/usr/local/python3/lib/python3.6/site-packages/flask/app.py", line 1951, in full_dispatch_request
    rv = self.handle_user_exception(e)
  File "/usr/local/python3/lib/python3.6/site-packages/flask/app.py", line 1820, in handle_user_exception
    reraise(exc_type, exc_value, tb)
  File "/usr/local/python3/lib/python3.6/site-packages/flask/_compat.py", line 39, in reraise
    raise value
  File "/usr/local/python3/lib/python3.6/site-packages/flask/app.py", line 1949, in full_dispatch_request
    rv = self.dispatch_request()
  File "/usr/local/python3/lib/python3.6/site-packages/flask/app.py", line 1935, in dispatch_request
    return self.view_functions[rule.endpoint](**req.view_args)
  File "/usr/local/webserver/FSS/app.py", line 21, in login
    login_or_success, login_message = JL.login_vpn()
  File "./UserLogin/UserOperator.py", line 38, in login_vpn
    v_username, v_password = VA.get_can_use_account()
  File "./VPN/vpnAccountManage.py", line 87, in get_can_use_account
    stats = self.vpn_account_or_useing(username, password)
  File "./VPN/vpnAccountManage.py", line 50, in vpn_account_or_useing
    raise Exception('连接失败:{}'.format(e))
Exception: 连接失败:HTTPSConnectionPool(host='vpn.just.edu.cn', port=443): Max retries exceeded with url: /dana-na/auth/url_default/login.cgi (Caused by NewConnectionError('<urllib3.connection.VerifiedHTTPSConnection object at 0x7f7740e2f898>: Failed to establish a new connection: [Errno 110] Connection timed out',))
[pid: 11915|app: 0|req: 31/45] 223.104.145.33 () {38 vars in 527 bytes} [Wed Oct 23 20:53:56 2019] POST /login/ => generated 290 bytes in 127346 msecs (HTTP/1.1 500) 2 headers in 84 bytes (1 switches on core 0)
已登录
[pid: 11915|app: 0|req: 32/46] 223.104.145.33 () {38 vars in 527 bytes} [Wed Oct 23 20:56:22 2019] POST /login/ => generated 85 bytes in 1164 msecs (HTTP/1.1 200) 2 headers in 71 bytes (1 switches on core 1)
已登录
[pid: 11913|app: 0|req: 15/47] 58.217.103.52 () {38 vars in 525 bytes} [Wed Oct 23 20:58:29 2019] POST /login/ => generated 85 bytes in 1082 msecs (HTTP/1.1 200) 2 headers in 71 bytes (1 switches on core 0)
[2019-10-23 20:59:25,103] ERROR in app: Exception on /login/ [POST]
Traceback (most recent call last):
  File "/usr/local/python3/lib/python3.6/site-packages/urllib3/connection.py", line 157, in _new_conn
    (self._dns_host, self.port), self.timeout, **extra_kw
  File "/usr/local/python3/lib/python3.6/site-packages/urllib3/util/connection.py", line 84, in create_connection
    raise err
  File "/usr/local/python3/lib/python3.6/site-packages/urllib3/util/connection.py", line 74, in create_connection
    sock.connect(sa)
TimeoutError: [Errno 110] Connection timed out

During handling of the above exception, another exception occurred:

Traceback (most recent call last):
  File "/usr/local/python3/lib/python3.6/site-packages/urllib3/connectionpool.py", line 672, in urlopen
    chunked=chunked,
  File "/usr/local/python3/lib/python3.6/site-packages/urllib3/connectionpool.py", line 376, in _make_request
    self._validate_conn(conn)
  File "/usr/local/python3/lib/python3.6/site-packages/urllib3/connectionpool.py", line 994, in _validate_conn
    conn.connect()
  File "/usr/local/python3/lib/python3.6/site-packages/urllib3/connection.py", line 334, in connect
    conn = self._new_conn()
  File "/usr/local/python3/lib/python3.6/site-packages/urllib3/connection.py", line 169, in _new_conn
    self, "Failed to establish a new connection: %s" % e
urllib3.exceptions.NewConnectionError: <urllib3.connection.VerifiedHTTPSConnection object at 0x7f774056c5c0>: Failed to establish a new connection: [Errno 110] Connection timed out

During handling of the above exception, another exception occurred:

Traceback (most recent call last):
  File "/usr/local/python3/lib/python3.6/site-packages/requests/adapters.py", line 449, in send
    timeout=timeout
  File "/usr/local/python3/lib/python3.6/site-packages/urllib3/connectionpool.py", line 720, in urlopen
    method, url, error=e, _pool=self, _stacktrace=sys.exc_info()[2]
  File "/usr/local/python3/lib/python3.6/site-packages/urllib3/util/retry.py", line 436, in increment
    raise MaxRetryError(_pool, url, error or ResponseError(cause))
urllib3.exceptions.MaxRetryError: HTTPSConnectionPool(host='vpn.just.edu.cn', port=443): Max retries exceeded with url: /dana-na/auth/url_default/login.cgi (Caused by NewConnectionError('<urllib3.connection.VerifiedHTTPSConnection object at 0x7f774056c5c0>: Failed to establish a new connection: [Errno 110] Connection timed out',))

During handling of the above exception, another exception occurred:

Traceback (most recent call last):
  File "./VPN/vpnAccountManage.py", line 48, in vpn_account_or_useing
    link = session.post(url=url, data=vpn_data, cookies=cookies, headers=headers, verify=False)
  File "/usr/local/python3/lib/python3.6/site-packages/requests/sessions.py", line 581, in post
    return self.request('POST', url, data=data, json=json, **kwargs)
  File "/usr/local/python3/lib/python3.6/site-packages/requests/sessions.py", line 533, in request
    resp = self.send(prep, **send_kwargs)
  File "/usr/local/python3/lib/python3.6/site-packages/requests/sessions.py", line 646, in send
    r = adapter.send(request, **kwargs)
  File "/usr/local/python3/lib/python3.6/site-packages/requests/adapters.py", line 516, in send
    raise ConnectionError(e, request=request)
requests.exceptions.ConnectionError: HTTPSConnectionPool(host='vpn.just.edu.cn', port=443): Max retries exceeded with url: /dana-na/auth/url_default/login.cgi (Caused by NewConnectionError('<urllib3.connection.VerifiedHTTPSConnection object at 0x7f774056c5c0>: Failed to establish a new connection: [Errno 110] Connection timed out',))

During handling of the above exception, another exception occurred:

Traceback (most recent call last):
  File "/usr/local/python3/lib/python3.6/site-packages/flask/app.py", line 2446, in wsgi_app
    response = self.full_dispatch_request()
  File "/usr/local/python3/lib/python3.6/site-packages/flask/app.py", line 1951, in full_dispatch_request
    rv = self.handle_user_exception(e)
  File "/usr/local/python3/lib/python3.6/site-packages/flask/app.py", line 1820, in handle_user_exception
    reraise(exc_type, exc_value, tb)
  File "/usr/local/python3/lib/python3.6/site-packages/flask/_compat.py", line 39, in reraise
    raise value
  File "/usr/local/python3/lib/python3.6/site-packages/flask/app.py", line 1949, in full_dispatch_request
    rv = self.dispatch_request()
  File "/usr/local/python3/lib/python3.6/site-packages/flask/app.py", line 1935, in dispatch_request
    return self.view_functions[rule.endpoint](**req.view_args)
  File "/usr/local/webserver/FSS/app.py", line 21, in login
    login_or_success, login_message = JL.login_vpn()
  File "./UserLogin/UserOperator.py", line 38, in login_vpn
    v_username, v_password = VA.get_can_use_account()
  File "./VPN/vpnAccountManage.py", line 87, in get_can_use_account
    stats = self.vpn_account_or_useing(username, password)
  File "./VPN/vpnAccountManage.py", line 50, in vpn_account_or_useing
    raise Exception('连接失败:{}'.format(e))
Exception: 连接失败:HTTPSConnectionPool(host='vpn.just.edu.cn', port=443): Max retries exceeded with url: /dana-na/auth/url_default/login.cgi (Caused by NewConnectionError('<urllib3.connection.VerifiedHTTPSConnection object at 0x7f774056c5c0>: Failed to establish a new connection: [Errno 110] Connection timed out',))
[pid: 11915|app: 0|req: 34/48] 58.217.103.52 () {38 vars in 526 bytes} [Wed Oct 23 20:57:17 2019] POST /login/ => generated 290 bytes in 127788 msecs (HTTP/1.1 500) 2 headers in 84 bytes (1 switches on core 0)
[2019-10-23 20:59:33,040] ERROR in app: Exception on /login/ [POST]
Traceback (most recent call last):
  File "/usr/local/python3/lib/python3.6/site-packages/urllib3/connection.py", line 157, in _new_conn
    (self._dns_host, self.port), self.timeout, **extra_kw
  File "/usr/local/python3/lib/python3.6/site-packages/urllib3/util/connection.py", line 84, in create_connection
    raise err
  File "/usr/local/python3/lib/python3.6/site-packages/urllib3/util/connection.py", line 74, in create_connection
    sock.connect(sa)
TimeoutError: [Errno 110] Connection timed out

During handling of the above exception, another exception occurred:

Traceback (most recent call last):
  File "/usr/local/python3/lib/python3.6/site-packages/urllib3/connectionpool.py", line 672, in urlopen
    chunked=chunked,
  File "/usr/local/python3/lib/python3.6/site-packages/urllib3/connectionpool.py", line 376, in _make_request
    self._validate_conn(conn)
  File "/usr/local/python3/lib/python3.6/site-packages/urllib3/connectionpool.py", line 994, in _validate_conn
    conn.connect()
  File "/usr/local/python3/lib/python3.6/site-packages/urllib3/connection.py", line 334, in connect
    conn = self._new_conn()
  File "/usr/local/python3/lib/python3.6/site-packages/urllib3/connection.py", line 169, in _new_conn
    self, "Failed to establish a new connection: %s" % e
urllib3.exceptions.NewConnectionError: <urllib3.connection.VerifiedHTTPSConnection object at 0x7f77405638d0>: Failed to establish a new connection: [Errno 110] Connection timed out

During handling of the above exception, another exception occurred:

Traceback (most recent call last):
  File "/usr/local/python3/lib/python3.6/site-packages/requests/adapters.py", line 449, in send
    timeout=timeout
  File "/usr/local/python3/lib/python3.6/site-packages/urllib3/connectionpool.py", line 720, in urlopen
    method, url, error=e, _pool=self, _stacktrace=sys.exc_info()[2]
  File "/usr/local/python3/lib/python3.6/site-packages/urllib3/util/retry.py", line 436, in increment
    raise MaxRetryError(_pool, url, error or ResponseError(cause))
urllib3.exceptions.MaxRetryError: HTTPSConnectionPool(host='vpn.just.edu.cn', port=443): Max retries exceeded with url: /dana-na/auth/url_default/login.cgi (Caused by NewConnectionError('<urllib3.connection.VerifiedHTTPSConnection object at 0x7f77405638d0>: Failed to establish a new connection: [Errno 110] Connection timed out',))

During handling of the above exception, another exception occurred:

Traceback (most recent call last):
  File "./VPN/vpnAccountManage.py", line 48, in vpn_account_or_useing
    link = session.post(url=url, data=vpn_data, cookies=cookies, headers=headers, verify=False)
  File "/usr/local/python3/lib/python3.6/site-packages/requests/sessions.py", line 581, in post
    return self.request('POST', url, data=data, json=json, **kwargs)
  File "/usr/local/python3/lib/python3.6/site-packages/requests/sessions.py", line 533, in request
    resp = self.send(prep, **send_kwargs)
  File "/usr/local/python3/lib/python3.6/site-packages/requests/sessions.py", line 646, in send
    r = adapter.send(request, **kwargs)
  File "/usr/local/python3/lib/python3.6/site-packages/requests/adapters.py", line 516, in send
    raise ConnectionError(e, request=request)
requests.exceptions.ConnectionError: HTTPSConnectionPool(host='vpn.just.edu.cn', port=443): Max retries exceeded with url: /dana-na/auth/url_default/login.cgi (Caused by NewConnectionError('<urllib3.connection.VerifiedHTTPSConnection object at 0x7f77405638d0>: Failed to establish a new connection: [Errno 110] Connection timed out',))

During handling of the above exception, another exception occurred:

Traceback (most recent call last):
  File "/usr/local/python3/lib/python3.6/site-packages/flask/app.py", line 2446, in wsgi_app
    response = self.full_dispatch_request()
  File "/usr/local/python3/lib/python3.6/site-packages/flask/app.py", line 1951, in full_dispatch_request
    rv = self.handle_user_exception(e)
  File "/usr/local/python3/lib/python3.6/site-packages/flask/app.py", line 1820, in handle_user_exception
    reraise(exc_type, exc_value, tb)
  File "/usr/local/python3/lib/python3.6/site-packages/flask/_compat.py", line 39, in reraise
    raise value
  File "/usr/local/python3/lib/python3.6/site-packages/flask/app.py", line 1949, in full_dispatch_request
    rv = self.dispatch_request()
  File "/usr/local/python3/lib/python3.6/site-packages/flask/app.py", line 1935, in dispatch_request
    return self.view_functions[rule.endpoint](**req.view_args)
  File "/usr/local/webserver/FSS/app.py", line 21, in login
    login_or_success, login_message = JL.login_vpn()
  File "./UserLogin/UserOperator.py", line 38, in login_vpn
    v_username, v_password = VA.get_can_use_account()
  File "./VPN/vpnAccountManage.py", line 87, in get_can_use_account
    stats = self.vpn_account_or_useing(username, password)
  File "./VPN/vpnAccountManage.py", line 50, in vpn_account_or_useing
    raise Exception('连接失败:{}'.format(e))
Exception: 连接失败:HTTPSConnectionPool(host='vpn.just.edu.cn', port=443): Max retries exceeded with url: /dana-na/auth/url_default/login.cgi (Caused by NewConnectionError('<urllib3.connection.VerifiedHTTPSConnection object at 0x7f77405638d0>: Failed to establish a new connection: [Errno 110] Connection timed out',))
[pid: 11915|app: 0|req: 34/49] 58.217.103.52 () {38 vars in 526 bytes} [Wed Oct 23 20:57:25 2019] POST /login/ => generated 290 bytes in 127395 msecs (HTTP/1.1 500) 2 headers in 84 bytes (1 switches on core 1)
已登录
[pid: 11915|app: 0|req: 35/50] 58.217.103.52 () {38 vars in 526 bytes} [Wed Oct 23 20:59:44 2019] POST /login/ => generated 85 bytes in 986 msecs (HTTP/1.1 200) 2 headers in 71 bytes (1 switches on core 0)
[2019-10-23 21:07:44,943] ERROR in app: Exception on /login/ [POST]
Traceback (most recent call last):
  File "/usr/local/python3/lib/python3.6/site-packages/urllib3/connection.py", line 157, in _new_conn
    (self._dns_host, self.port), self.timeout, **extra_kw
  File "/usr/local/python3/lib/python3.6/site-packages/urllib3/util/connection.py", line 84, in create_connection
    raise err
  File "/usr/local/python3/lib/python3.6/site-packages/urllib3/util/connection.py", line 74, in create_connection
    sock.connect(sa)
TimeoutError: [Errno 110] Connection timed out

During handling of the above exception, another exception occurred:

Traceback (most recent call last):
  File "/usr/local/python3/lib/python3.6/site-packages/urllib3/connectionpool.py", line 672, in urlopen
    chunked=chunked,
  File "/usr/local/python3/lib/python3.6/site-packages/urllib3/connectionpool.py", line 376, in _make_request
    self._validate_conn(conn)
  File "/usr/local/python3/lib/python3.6/site-packages/urllib3/connectionpool.py", line 994, in _validate_conn
    conn.connect()
  File "/usr/local/python3/lib/python3.6/site-packages/urllib3/connection.py", line 334, in connect
    conn = self._new_conn()
  File "/usr/local/python3/lib/python3.6/site-packages/urllib3/connection.py", line 169, in _new_conn
    self, "Failed to establish a new connection: %s" % e
urllib3.exceptions.NewConnectionError: <urllib3.connection.VerifiedHTTPSConnection object at 0x7f7740906eb8>: Failed to establish a new connection: [Errno 110] Connection timed out

During handling of the above exception, another exception occurred:

Traceback (most recent call last):
  File "/usr/local/python3/lib/python3.6/site-packages/requests/adapters.py", line 449, in send
    timeout=timeout
  File "/usr/local/python3/lib/python3.6/site-packages/urllib3/connectionpool.py", line 720, in urlopen
    method, url, error=e, _pool=self, _stacktrace=sys.exc_info()[2]
  File "/usr/local/python3/lib/python3.6/site-packages/urllib3/util/retry.py", line 436, in increment
    raise MaxRetryError(_pool, url, error or ResponseError(cause))
urllib3.exceptions.MaxRetryError: HTTPSConnectionPool(host='vpn.just.edu.cn', port=443): Max retries exceeded with url: /dana-na/auth/url_default/login.cgi (Caused by NewConnectionError('<urllib3.connection.VerifiedHTTPSConnection object at 0x7f7740906eb8>: Failed to establish a new connection: [Errno 110] Connection timed out',))

During handling of the above exception, another exception occurred:

Traceback (most recent call last):
  File "./VPN/vpnAccountManage.py", line 48, in vpn_account_or_useing
    link = session.post(url=url, data=vpn_data, cookies=cookies, headers=headers, verify=False)
  File "/usr/local/python3/lib/python3.6/site-packages/requests/sessions.py", line 581, in post
    return self.request('POST', url, data=data, json=json, **kwargs)
  File "/usr/local/python3/lib/python3.6/site-packages/requests/sessions.py", line 533, in request
    resp = self.send(prep, **send_kwargs)
  File "/usr/local/python3/lib/python3.6/site-packages/requests/sessions.py", line 646, in send
    r = adapter.send(request, **kwargs)
  File "/usr/local/python3/lib/python3.6/site-packages/requests/adapters.py", line 516, in send
    raise ConnectionError(e, request=request)
requests.exceptions.ConnectionError: HTTPSConnectionPool(host='vpn.just.edu.cn', port=443): Max retries exceeded with url: /dana-na/auth/url_default/login.cgi (Caused by NewConnectionError('<urllib3.connection.VerifiedHTTPSConnection object at 0x7f7740906eb8>: Failed to establish a new connection: [Errno 110] Connection timed out',))

During handling of the above exception, another exception occurred:

Traceback (most recent call last):
  File "/usr/local/python3/lib/python3.6/site-packages/flask/app.py", line 2446, in wsgi_app
    response = self.full_dispatch_request()
  File "/usr/local/python3/lib/python3.6/site-packages/flask/app.py", line 1951, in full_dispatch_request
    rv = self.handle_user_exception(e)
  File "/usr/local/python3/lib/python3.6/site-packages/flask/app.py", line 1820, in handle_user_exception
    reraise(exc_type, exc_value, tb)
  File "/usr/local/python3/lib/python3.6/site-packages/flask/_compat.py", line 39, in reraise
    raise value
  File "/usr/local/python3/lib/python3.6/site-packages/flask/app.py", line 1949, in full_dispatch_request
    rv = self.dispatch_request()
  File "/usr/local/python3/lib/python3.6/site-packages/flask/app.py", line 1935, in dispatch_request
    return self.view_functions[rule.endpoint](**req.view_args)
  File "/usr/local/webserver/FSS/app.py", line 21, in login
    login_or_success, login_message = JL.login_vpn()
  File "./UserLogin/UserOperator.py", line 38, in login_vpn
    v_username, v_password = VA.get_can_use_account()
  File "./VPN/vpnAccountManage.py", line 87, in get_can_use_account
    stats = self.vpn_account_or_useing(username, password)
  File "./VPN/vpnAccountManage.py", line 50, in vpn_account_or_useing
    raise Exception('连接失败:{}'.format(e))
Exception: 连接失败:HTTPSConnectionPool(host='vpn.just.edu.cn', port=443): Max retries exceeded with url: /dana-na/auth/url_default/login.cgi (Caused by NewConnectionError('<urllib3.connection.VerifiedHTTPSConnection object at 0x7f7740906eb8>: Failed to establish a new connection: [Errno 110] Connection timed out',))
[pid: 11915|app: 0|req: 36/51] 58.217.103.52 () {38 vars in 526 bytes} [Wed Oct 23 21:05:37 2019] POST /login/ => generated 290 bytes in 127391 msecs (HTTP/1.1 500) 2 headers in 84 bytes (1 switches on core 1)
[pid: 11915|app: 0|req: 38/52] 58.217.103.52 () {40 vars in 667 bytes} [Wed Oct 23 21:14:26 2019] GET / => generated 336 bytes in 0 msecs (HTTP/1.1 200) 2 headers in 80 bytes (1 switches on core 1)
已登录
[pid: 11913|app: 0|req: 16/53] 58.217.103.52 () {38 vars in 526 bytes} [Wed Oct 23 21:15:33 2019] POST /login/ => generated 85 bytes in 1133 msecs (HTTP/1.1 200) 2 headers in 71 bytes (1 switches on core 1)
[2019-10-23 21:15:49,807] ERROR in app: Exception on /login/ [POST]
Traceback (most recent call last):
  File "/usr/local/python3/lib/python3.6/site-packages/urllib3/connection.py", line 157, in _new_conn
    (self._dns_host, self.port), self.timeout, **extra_kw
  File "/usr/local/python3/lib/python3.6/site-packages/urllib3/util/connection.py", line 84, in create_connection
    raise err
  File "/usr/local/python3/lib/python3.6/site-packages/urllib3/util/connection.py", line 74, in create_connection
    sock.connect(sa)
TimeoutError: [Errno 110] Connection timed out

During handling of the above exception, another exception occurred:

Traceback (most recent call last):
  File "/usr/local/python3/lib/python3.6/site-packages/urllib3/connectionpool.py", line 672, in urlopen
    chunked=chunked,
  File "/usr/local/python3/lib/python3.6/site-packages/urllib3/connectionpool.py", line 376, in _make_request
    self._validate_conn(conn)
  File "/usr/local/python3/lib/python3.6/site-packages/urllib3/connectionpool.py", line 994, in _validate_conn
    conn.connect()
  File "/usr/local/python3/lib/python3.6/site-packages/urllib3/connection.py", line 334, in connect
    conn = self._new_conn()
  File "/usr/local/python3/lib/python3.6/site-packages/urllib3/connection.py", line 169, in _new_conn
    self, "Failed to establish a new connection: %s" % e
urllib3.exceptions.NewConnectionError: <urllib3.connection.VerifiedHTTPSConnection object at 0x7f7740559550>: Failed to establish a new connection: [Errno 110] Connection timed out

During handling of the above exception, another exception occurred:

Traceback (most recent call last):
  File "/usr/local/python3/lib/python3.6/site-packages/requests/adapters.py", line 449, in send
    timeout=timeout
  File "/usr/local/python3/lib/python3.6/site-packages/urllib3/connectionpool.py", line 720, in urlopen
    method, url, error=e, _pool=self, _stacktrace=sys.exc_info()[2]
  File "/usr/local/python3/lib/python3.6/site-packages/urllib3/util/retry.py", line 436, in increment
    raise MaxRetryError(_pool, url, error or ResponseError(cause))
urllib3.exceptions.MaxRetryError: HTTPSConnectionPool(host='vpn.just.edu.cn', port=443): Max retries exceeded with url: /dana-na/auth/url_default/login.cgi (Caused by NewConnectionError('<urllib3.connection.VerifiedHTTPSConnection object at 0x7f7740559550>: Failed to establish a new connection: [Errno 110] Connection timed out',))

During handling of the above exception, another exception occurred:

Traceback (most recent call last):
  File "./VPN/vpnAccountManage.py", line 48, in vpn_account_or_useing
    requests.packages.urllib3.disable_warnings()
  File "/usr/local/python3/lib/python3.6/site-packages/requests/sessions.py", line 581, in post
    return self.request('POST', url, data=data, json=json, **kwargs)
  File "/usr/local/python3/lib/python3.6/site-packages/requests/sessions.py", line 533, in request
    resp = self.send(prep, **send_kwargs)
  File "/usr/local/python3/lib/python3.6/site-packages/requests/sessions.py", line 646, in send
    r = adapter.send(request, **kwargs)
  File "/usr/local/python3/lib/python3.6/site-packages/requests/adapters.py", line 516, in send
    raise ConnectionError(e, request=request)
requests.exceptions.ConnectionError: HTTPSConnectionPool(host='vpn.just.edu.cn', port=443): Max retries exceeded with url: /dana-na/auth/url_default/login.cgi (Caused by NewConnectionError('<urllib3.connection.VerifiedHTTPSConnection object at 0x7f7740559550>: Failed to establish a new connection: [Errno 110] Connection timed out',))

During handling of the above exception, another exception occurred:

Traceback (most recent call last):
  File "/usr/local/python3/lib/python3.6/site-packages/flask/app.py", line 2446, in wsgi_app
    response = self.full_dispatch_request()
  File "/usr/local/python3/lib/python3.6/site-packages/flask/app.py", line 1951, in full_dispatch_request
    rv = self.handle_user_exception(e)
  File "/usr/local/python3/lib/python3.6/site-packages/flask/app.py", line 1820, in handle_user_exception
    reraise(exc_type, exc_value, tb)
  File "/usr/local/python3/lib/python3.6/site-packages/flask/_compat.py", line 39, in reraise
    raise value
  File "/usr/local/python3/lib/python3.6/site-packages/flask/app.py", line 1949, in full_dispatch_request
    rv = self.dispatch_request()
  File "/usr/local/python3/lib/python3.6/site-packages/flask/app.py", line 1935, in dispatch_request
    return self.view_functions[rule.endpoint](**req.view_args)
  File "/usr/local/webserver/FSS/app.py", line 21, in login
    login_or_success, login_message = JL.login_vpn()
  File "./UserLogin/UserOperator.py", line 38, in login_vpn
    v_username, v_password = VA.get_can_use_account()
  File "./VPN/vpnAccountManage.py", line 87, in get_can_use_account
    for username, password in self.account_list.items():
  File "./VPN/vpnAccountManage.py", line 50, in vpn_account_or_useing
    except Exception as e:
Exception: 连接失败:HTTPSConnectionPool(host='vpn.just.edu.cn', port=443): Max retries exceeded with url: /dana-na/auth/url_default/login.cgi (Caused by NewConnectionError('<urllib3.connection.VerifiedHTTPSConnection object at 0x7f7740559550>: Failed to establish a new connection: [Errno 110] Connection timed out',))
[pid: 11915|app: 0|req: 39/54] 58.217.103.52 () {38 vars in 526 bytes} [Wed Oct 23 21:13:42 2019] POST /login/ => generated 290 bytes in 127366 msecs (HTTP/1.1 500) 2 headers in 84 bytes (1 switches on core 0)
已登录
[pid: 11915|app: 0|req: 40/55] 58.217.103.52 () {38 vars in 526 bytes} [Wed Oct 23 21:15:56 2019] POST /login/ => generated 85 bytes in 1231 msecs (HTTP/1.1 200) 2 headers in 71 bytes (1 switches on core 0)
已登录
[pid: 11915|app: 0|req: 41/56] 58.217.103.52 () {38 vars in 525 bytes} [Wed Oct 23 21:16:02 2019] POST /login/ => generated 85 bytes in 1150 msecs (HTTP/1.1 200) 2 headers in 71 bytes (1 switches on core 0)
[pid: 11913|app: 0|req: 17/57] 195.205.161.58 () {32 vars in 466 bytes} [Wed Oct 23 21:16:22 2019] GET / => generated 336 bytes in 6 msecs (HTTP/1.1 200) 2 headers in 80 bytes (1 switches on core 0)
已登录
[pid: 11915|app: 0|req: 42/58] 223.104.145.33 () {38 vars in 527 bytes} [Wed Oct 23 21:16:21 2019] POST /login/ => generated 85 bytes in 1206 msecs (HTTP/1.1 200) 2 headers in 71 bytes (1 switches on core 0)
[2019-10-23 21:16:39,599] ERROR in app: Exception on /login/ [POST]
Traceback (most recent call last):
  File "/usr/local/python3/lib/python3.6/site-packages/urllib3/connection.py", line 157, in _new_conn
    (self._dns_host, self.port), self.timeout, **extra_kw
  File "/usr/local/python3/lib/python3.6/site-packages/urllib3/util/connection.py", line 84, in create_connection
    raise err
  File "/usr/local/python3/lib/python3.6/site-packages/urllib3/util/connection.py", line 74, in create_connection
    sock.connect(sa)
TimeoutError: [Errno 110] Connection timed out

During handling of the above exception, another exception occurred:

Traceback (most recent call last):
  File "/usr/local/python3/lib/python3.6/site-packages/urllib3/connectionpool.py", line 672, in urlopen
    chunked=chunked,
  File "/usr/local/python3/lib/python3.6/site-packages/urllib3/connectionpool.py", line 376, in _make_request
    self._validate_conn(conn)
  File "/usr/local/python3/lib/python3.6/site-packages/urllib3/connectionpool.py", line 994, in _validate_conn
    conn.connect()
  File "/usr/local/python3/lib/python3.6/site-packages/urllib3/connection.py", line 334, in connect
    conn = self._new_conn()
  File "/usr/local/python3/lib/python3.6/site-packages/urllib3/connection.py", line 169, in _new_conn
    self, "Failed to establish a new connection: %s" % e
urllib3.exceptions.NewConnectionError: <urllib3.connection.VerifiedHTTPSConnection object at 0x7f7740909f60>: Failed to establish a new connection: [Errno 110] Connection timed out

During handling of the above exception, another exception occurred:

Traceback (most recent call last):
  File "/usr/local/python3/lib/python3.6/site-packages/requests/adapters.py", line 449, in send
    timeout=timeout
  File "/usr/local/python3/lib/python3.6/site-packages/urllib3/connectionpool.py", line 720, in urlopen
    method, url, error=e, _pool=self, _stacktrace=sys.exc_info()[2]
  File "/usr/local/python3/lib/python3.6/site-packages/urllib3/util/retry.py", line 436, in increment
    raise MaxRetryError(_pool, url, error or ResponseError(cause))
urllib3.exceptions.MaxRetryError: HTTPSConnectionPool(host='vpn.just.edu.cn', port=443): Max retries exceeded with url: /dana-na/auth/url_default/login.cgi (Caused by NewConnectionError('<urllib3.connection.VerifiedHTTPSConnection object at 0x7f7740909f60>: Failed to establish a new connection: [Errno 110] Connection timed out',))

During handling of the above exception, another exception occurred:

Traceback (most recent call last):
  File "./VPN/vpnAccountManage.py", line 48, in vpn_account_or_useing
    requests.packages.urllib3.disable_warnings()
  File "/usr/local/python3/lib/python3.6/site-packages/requests/sessions.py", line 581, in post
    return self.request('POST', url, data=data, json=json, **kwargs)
  File "/usr/local/python3/lib/python3.6/site-packages/requests/sessions.py", line 533, in request
    resp = self.send(prep, **send_kwargs)
  File "/usr/local/python3/lib/python3.6/site-packages/requests/sessions.py", line 646, in send
    r = adapter.send(request, **kwargs)
  File "/usr/local/python3/lib/python3.6/site-packages/requests/adapters.py", line 516, in send
    raise ConnectionError(e, request=request)
requests.exceptions.ConnectionError: HTTPSConnectionPool(host='vpn.just.edu.cn', port=443): Max retries exceeded with url: /dana-na/auth/url_default/login.cgi (Caused by NewConnectionError('<urllib3.connection.VerifiedHTTPSConnection object at 0x7f7740909f60>: Failed to establish a new connection: [Errno 110] Connection timed out',))

During handling of the above exception, another exception occurred:

Traceback (most recent call last):
  File "/usr/local/python3/lib/python3.6/site-packages/flask/app.py", line 2446, in wsgi_app
    response = self.full_dispatch_request()
  File "/usr/local/python3/lib/python3.6/site-packages/flask/app.py", line 1951, in full_dispatch_request
    rv = self.handle_user_exception(e)
  File "/usr/local/python3/lib/python3.6/site-packages/flask/app.py", line 1820, in handle_user_exception
    reraise(exc_type, exc_value, tb)
  File "/usr/local/python3/lib/python3.6/site-packages/flask/_compat.py", line 39, in reraise
    raise value
  File "/usr/local/python3/lib/python3.6/site-packages/flask/app.py", line 1949, in full_dispatch_request
    rv = self.dispatch_request()
  File "/usr/local/python3/lib/python3.6/site-packages/flask/app.py", line 1935, in dispatch_request
    return self.view_functions[rule.endpoint](**req.view_args)
  File "/usr/local/webserver/FSS/app.py", line 21, in login
    login_or_success, login_message = JL.login_vpn()
  File "./UserLogin/UserOperator.py", line 38, in login_vpn
    v_username, v_password = VA.get_can_use_account()
  File "./VPN/vpnAccountManage.py", line 87, in get_can_use_account
    for username, password in self.account_list.items():
  File "./VPN/vpnAccountManage.py", line 50, in vpn_account_or_useing
    except Exception as e:
Exception: 连接失败:HTTPSConnectionPool(host='vpn.just.edu.cn', port=443): Max retries exceeded with url: /dana-na/auth/url_default/login.cgi (Caused by NewConnectionError('<urllib3.connection.VerifiedHTTPSConnection object at 0x7f7740909f60>: Failed to establish a new connection: [Errno 110] Connection timed out',))
[pid: 11915|app: 0|req: 42/59] 58.217.103.52 () {38 vars in 525 bytes} [Wed Oct 23 21:14:32 2019] POST /login/ => generated 290 bytes in 127398 msecs (HTTP/1.1 500) 2 headers in 84 bytes (1 switches on core 1)
[2019-10-23 21:19:13,455] ERROR in app: Exception on /get_schedule/ [POST]
Traceback (most recent call last):
  File "/usr/local/python3/lib/python3.6/site-packages/urllib3/connection.py", line 157, in _new_conn
    (self._dns_host, self.port), self.timeout, **extra_kw
  File "/usr/local/python3/lib/python3.6/site-packages/urllib3/util/connection.py", line 84, in create_connection
    raise err
  File "/usr/local/python3/lib/python3.6/site-packages/urllib3/util/connection.py", line 74, in create_connection
    sock.connect(sa)
TimeoutError: [Errno 110] Connection timed out

During handling of the above exception, another exception occurred:

Traceback (most recent call last):
  File "/usr/local/python3/lib/python3.6/site-packages/urllib3/connectionpool.py", line 672, in urlopen
    chunked=chunked,
  File "/usr/local/python3/lib/python3.6/site-packages/urllib3/connectionpool.py", line 376, in _make_request
    self._validate_conn(conn)
  File "/usr/local/python3/lib/python3.6/site-packages/urllib3/connectionpool.py", line 994, in _validate_conn
    conn.connect()
  File "/usr/local/python3/lib/python3.6/site-packages/urllib3/connection.py", line 334, in connect
    conn = self._new_conn()
  File "/usr/local/python3/lib/python3.6/site-packages/urllib3/connection.py", line 169, in _new_conn
    self, "Failed to establish a new connection: %s" % e
urllib3.exceptions.NewConnectionError: <urllib3.connection.VerifiedHTTPSConnection object at 0x7f7740933390>: Failed to establish a new connection: [Errno 110] Connection timed out

During handling of the above exception, another exception occurred:

Traceback (most recent call last):
  File "/usr/local/python3/lib/python3.6/site-packages/requests/adapters.py", line 449, in send
    timeout=timeout
  File "/usr/local/python3/lib/python3.6/site-packages/urllib3/connectionpool.py", line 720, in urlopen
    method, url, error=e, _pool=self, _stacktrace=sys.exc_info()[2]
  File "/usr/local/python3/lib/python3.6/site-packages/urllib3/util/retry.py", line 436, in increment
    raise MaxRetryError(_pool, url, error or ResponseError(cause))
urllib3.exceptions.MaxRetryError: HTTPSConnectionPool(host='vpn.just.edu.cn', port=443): Max retries exceeded with url: /dana-na/auth/url_default/login.cgi (Caused by NewConnectionError('<urllib3.connection.VerifiedHTTPSConnection object at 0x7f7740933390>: Failed to establish a new connection: [Errno 110] Connection timed out',))

During handling of the above exception, another exception occurred:

Traceback (most recent call last):
  File "./VPN/vpnAccountManage.py", line 48, in vpn_account_or_useing
    requests.packages.urllib3.disable_warnings()
  File "/usr/local/python3/lib/python3.6/site-packages/requests/sessions.py", line 581, in post
    return self.request('POST', url, data=data, json=json, **kwargs)
  File "/usr/local/python3/lib/python3.6/site-packages/requests/sessions.py", line 533, in request
    resp = self.send(prep, **send_kwargs)
  File "/usr/local/python3/lib/python3.6/site-packages/requests/sessions.py", line 646, in send
    r = adapter.send(request, **kwargs)
  File "/usr/local/python3/lib/python3.6/site-packages/requests/adapters.py", line 516, in send
    raise ConnectionError(e, request=request)
requests.exceptions.ConnectionError: HTTPSConnectionPool(host='vpn.just.edu.cn', port=443): Max retries exceeded with url: /dana-na/auth/url_default/login.cgi (Caused by NewConnectionError('<urllib3.connection.VerifiedHTTPSConnection object at 0x7f7740933390>: Failed to establish a new connection: [Errno 110] Connection timed out',))

During handling of the above exception, another exception occurred:

Traceback (most recent call last):
  File "/usr/local/python3/lib/python3.6/site-packages/flask/app.py", line 2446, in wsgi_app
    response = self.full_dispatch_request()
  File "/usr/local/python3/lib/python3.6/site-packages/flask/app.py", line 1951, in full_dispatch_request
    rv = self.handle_user_exception(e)
  File "/usr/local/python3/lib/python3.6/site-packages/flask/app.py", line 1820, in handle_user_exception
    reraise(exc_type, exc_value, tb)
  File "/usr/local/python3/lib/python3.6/site-packages/flask/_compat.py", line 39, in reraise
    raise value
  File "/usr/local/python3/lib/python3.6/site-packages/flask/app.py", line 1949, in full_dispatch_request
    rv = self.dispatch_request()
  File "/usr/local/python3/lib/python3.6/site-packages/flask/app.py", line 1935, in dispatch_request
    return self.view_functions[rule.endpoint](**req.view_args)
  File "/usr/local/webserver/FSS/app.py", line 34, in schedule
    JL.login_vpn()
  File "./UserLogin/UserOperator.py", line 38, in login_vpn
    v_username, v_password = VA.get_can_use_account()
  File "./VPN/vpnAccountManage.py", line 87, in get_can_use_account
    for username, password in self.account_list.items():
  File "./VPN/vpnAccountManage.py", line 50, in vpn_account_or_useing
    except Exception as e:
Exception: 连接失败:HTTPSConnectionPool(host='vpn.just.edu.cn', port=443): Max retries exceeded with url: /dana-na/auth/url_default/login.cgi (Caused by NewConnectionError('<urllib3.connection.VerifiedHTTPSConnection object at 0x7f7740933390>: Failed to establish a new connection: [Errno 110] Connection timed out',))
[pid: 11915|app: 0|req: 44/60] 58.217.103.52 () {38 vars in 539 bytes} [Wed Oct 23 21:17:06 2019] POST /get_schedule/ => generated 290 bytes in 127327 msecs (HTTP/1.1 500) 2 headers in 84 bytes (1 switches on core 0)
[2019-10-23 21:20:17,071] ERROR in app: Exception on /get_schedule/ [POST]
Traceback (most recent call last):
  File "/usr/local/python3/lib/python3.6/site-packages/urllib3/connection.py", line 157, in _new_conn
    (self._dns_host, self.port), self.timeout, **extra_kw
  File "/usr/local/python3/lib/python3.6/site-packages/urllib3/util/connection.py", line 84, in create_connection
    raise err
  File "/usr/local/python3/lib/python3.6/site-packages/urllib3/util/connection.py", line 74, in create_connection
    sock.connect(sa)
TimeoutError: [Errno 110] Connection timed out

During handling of the above exception, another exception occurred:

Traceback (most recent call last):
  File "/usr/local/python3/lib/python3.6/site-packages/urllib3/connectionpool.py", line 672, in urlopen
    chunked=chunked,
  File "/usr/local/python3/lib/python3.6/site-packages/urllib3/connectionpool.py", line 376, in _make_request
    self._validate_conn(conn)
  File "/usr/local/python3/lib/python3.6/site-packages/urllib3/connectionpool.py", line 994, in _validate_conn
    conn.connect()
  File "/usr/local/python3/lib/python3.6/site-packages/urllib3/connection.py", line 334, in connect
    conn = self._new_conn()
  File "/usr/local/python3/lib/python3.6/site-packages/urllib3/connection.py", line 169, in _new_conn
    self, "Failed to establish a new connection: %s" % e
urllib3.exceptions.NewConnectionError: <urllib3.connection.VerifiedHTTPSConnection object at 0x7f774094c390>: Failed to establish a new connection: [Errno 110] Connection timed out

During handling of the above exception, another exception occurred:

Traceback (most recent call last):
  File "/usr/local/python3/lib/python3.6/site-packages/requests/adapters.py", line 449, in send
    timeout=timeout
  File "/usr/local/python3/lib/python3.6/site-packages/urllib3/connectionpool.py", line 720, in urlopen
    method, url, error=e, _pool=self, _stacktrace=sys.exc_info()[2]
  File "/usr/local/python3/lib/python3.6/site-packages/urllib3/util/retry.py", line 436, in increment
    raise MaxRetryError(_pool, url, error or ResponseError(cause))
urllib3.exceptions.MaxRetryError: HTTPSConnectionPool(host='vpn.just.edu.cn', port=443): Max retries exceeded with url: /dana-na/auth/url_default/login.cgi (Caused by NewConnectionError('<urllib3.connection.VerifiedHTTPSConnection object at 0x7f774094c390>: Failed to establish a new connection: [Errno 110] Connection timed out',))

During handling of the above exception, another exception occurred:

Traceback (most recent call last):
  File "./VPN/vpnAccountManage.py", line 48, in vpn_account_or_useing
    requests.packages.urllib3.disable_warnings()
  File "/usr/local/python3/lib/python3.6/site-packages/requests/sessions.py", line 581, in post
    return self.request('POST', url, data=data, json=json, **kwargs)
  File "/usr/local/python3/lib/python3.6/site-packages/requests/sessions.py", line 533, in request
    resp = self.send(prep, **send_kwargs)
  File "/usr/local/python3/lib/python3.6/site-packages/requests/sessions.py", line 646, in send
    r = adapter.send(request, **kwargs)
  File "/usr/local/python3/lib/python3.6/site-packages/requests/adapters.py", line 516, in send
    raise ConnectionError(e, request=request)
requests.exceptions.ConnectionError: HTTPSConnectionPool(host='vpn.just.edu.cn', port=443): Max retries exceeded with url: /dana-na/auth/url_default/login.cgi (Caused by NewConnectionError('<urllib3.connection.VerifiedHTTPSConnection object at 0x7f774094c390>: Failed to establish a new connection: [Errno 110] Connection timed out',))

During handling of the above exception, another exception occurred:

Traceback (most recent call last):
  File "/usr/local/python3/lib/python3.6/site-packages/flask/app.py", line 2446, in wsgi_app
    response = self.full_dispatch_request()
  File "/usr/local/python3/lib/python3.6/site-packages/flask/app.py", line 1951, in full_dispatch_request
    rv = self.handle_user_exception(e)
  File "/usr/local/python3/lib/python3.6/site-packages/flask/app.py", line 1820, in handle_user_exception
    reraise(exc_type, exc_value, tb)
  File "/usr/local/python3/lib/python3.6/site-packages/flask/_compat.py", line 39, in reraise
    raise value
  File "/usr/local/python3/lib/python3.6/site-packages/flask/app.py", line 1949, in full_dispatch_request
    rv = self.dispatch_request()
  File "/usr/local/python3/lib/python3.6/site-packages/flask/app.py", line 1935, in dispatch_request
    return self.view_functions[rule.endpoint](**req.view_args)
  File "/usr/local/webserver/FSS/app.py", line 34, in schedule
    JL.login_vpn()
  File "./UserLogin/UserOperator.py", line 38, in login_vpn
    v_username, v_password = VA.get_can_use_account()
  File "./VPN/vpnAccountManage.py", line 87, in get_can_use_account
    for username, password in self.account_list.items():
  File "./VPN/vpnAccountManage.py", line 50, in vpn_account_or_useing
    except Exception as e:
Exception: 连接失败:HTTPSConnectionPool(host='vpn.just.edu.cn', port=443): Max retries exceeded with url: /dana-na/auth/url_default/login.cgi (Caused by NewConnectionError('<urllib3.connection.VerifiedHTTPSConnection object at 0x7f774094c390>: Failed to establish a new connection: [Errno 110] Connection timed out',))
[pid: 11915|app: 0|req: 44/61] 58.217.103.52 () {38 vars in 540 bytes} [Wed Oct 23 21:18:09 2019] POST /get_schedule/ => generated 290 bytes in 127354 msecs (HTTP/1.1 500) 2 headers in 84 bytes (1 switches on core 1)
[2019-10-23 21:20:28,335] ERROR in app: Exception on /login/ [POST]
Traceback (most recent call last):
  File "/usr/local/python3/lib/python3.6/site-packages/urllib3/connection.py", line 157, in _new_conn
    (self._dns_host, self.port), self.timeout, **extra_kw
  File "/usr/local/python3/lib/python3.6/site-packages/urllib3/util/connection.py", line 84, in create_connection
    raise err
  File "/usr/local/python3/lib/python3.6/site-packages/urllib3/util/connection.py", line 74, in create_connection
    sock.connect(sa)
TimeoutError: [Errno 110] Connection timed out

During handling of the above exception, another exception occurred:

Traceback (most recent call last):
  File "/usr/local/python3/lib/python3.6/site-packages/urllib3/connectionpool.py", line 672, in urlopen
    chunked=chunked,
  File "/usr/local/python3/lib/python3.6/site-packages/urllib3/connectionpool.py", line 376, in _make_request
    self._validate_conn(conn)
  File "/usr/local/python3/lib/python3.6/site-packages/urllib3/connectionpool.py", line 994, in _validate_conn
    conn.connect()
  File "/usr/local/python3/lib/python3.6/site-packages/urllib3/connection.py", line 334, in connect
    conn = self._new_conn()
  File "/usr/local/python3/lib/python3.6/site-packages/urllib3/connection.py", line 169, in _new_conn
    self, "Failed to establish a new connection: %s" % e
urllib3.exceptions.NewConnectionError: <urllib3.connection.VerifiedHTTPSConnection object at 0x7f7740c4acf8>: Failed to establish a new connection: [Errno 110] Connection timed out

During handling of the above exception, another exception occurred:

Traceback (most recent call last):
  File "/usr/local/python3/lib/python3.6/site-packages/requests/adapters.py", line 449, in send
    timeout=timeout
  File "/usr/local/python3/lib/python3.6/site-packages/urllib3/connectionpool.py", line 720, in urlopen
    method, url, error=e, _pool=self, _stacktrace=sys.exc_info()[2]
  File "/usr/local/python3/lib/python3.6/site-packages/urllib3/util/retry.py", line 436, in increment
    raise MaxRetryError(_pool, url, error or ResponseError(cause))
urllib3.exceptions.MaxRetryError: HTTPSConnectionPool(host='vpn.just.edu.cn', port=443): Max retries exceeded with url: /dana-na/auth/url_default/login.cgi (Caused by NewConnectionError('<urllib3.connection.VerifiedHTTPSConnection object at 0x7f7740c4acf8>: Failed to establish a new connection: [Errno 110] Connection timed out',))

During handling of the above exception, another exception occurred:

Traceback (most recent call last):
  File "./VPN/vpnAccountManage.py", line 48, in vpn_account_or_useing
    requests.packages.urllib3.disable_warnings()
  File "/usr/local/python3/lib/python3.6/site-packages/requests/sessions.py", line 581, in post
    return self.request('POST', url, data=data, json=json, **kwargs)
  File "/usr/local/python3/lib/python3.6/site-packages/requests/sessions.py", line 533, in request
    resp = self.send(prep, **send_kwargs)
  File "/usr/local/python3/lib/python3.6/site-packages/requests/sessions.py", line 646, in send
    r = adapter.send(request, **kwargs)
  File "/usr/local/python3/lib/python3.6/site-packages/requests/adapters.py", line 516, in send
    raise ConnectionError(e, request=request)
requests.exceptions.ConnectionError: HTTPSConnectionPool(host='vpn.just.edu.cn', port=443): Max retries exceeded with url: /dana-na/auth/url_default/login.cgi (Caused by NewConnectionError('<urllib3.connection.VerifiedHTTPSConnection object at 0x7f7740c4acf8>: Failed to establish a new connection: [Errno 110] Connection timed out',))

During handling of the above exception, another exception occurred:

Traceback (most recent call last):
  File "/usr/local/python3/lib/python3.6/site-packages/flask/app.py", line 2446, in wsgi_app
    response = self.full_dispatch_request()
  File "/usr/local/python3/lib/python3.6/site-packages/flask/app.py", line 1951, in full_dispatch_request
    rv = self.handle_user_exception(e)
  File "/usr/local/python3/lib/python3.6/site-packages/flask/app.py", line 1820, in handle_user_exception
    reraise(exc_type, exc_value, tb)
  File "/usr/local/python3/lib/python3.6/site-packages/flask/_compat.py", line 39, in reraise
    raise value
  File "/usr/local/python3/lib/python3.6/site-packages/flask/app.py", line 1949, in full_dispatch_request
    rv = self.dispatch_request()
  File "/usr/local/python3/lib/python3.6/site-packages/flask/app.py", line 1935, in dispatch_request
    return self.view_functions[rule.endpoint](**req.view_args)
  File "/usr/local/webserver/FSS/app.py", line 21, in login
    login_or_success, login_message = JL.login_vpn()
  File "./UserLogin/UserOperator.py", line 38, in login_vpn
    v_username, v_password = VA.get_can_use_account()
  File "./VPN/vpnAccountManage.py", line 87, in get_can_use_account
    for username, password in self.account_list.items():
  File "./VPN/vpnAccountManage.py", line 50, in vpn_account_or_useing
    except Exception as e:
Exception: 连接失败:HTTPSConnectionPool(host='vpn.just.edu.cn', port=443): Max retries exceeded with url: /dana-na/auth/url_default/login.cgi (Caused by NewConnectionError('<urllib3.connection.VerifiedHTTPSConnection object at 0x7f7740c4acf8>: Failed to establish a new connection: [Errno 110] Connection timed out',))
[pid: 11913|app: 0|req: 18/62] 223.104.145.33 () {38 vars in 527 bytes} [Wed Oct 23 21:18:20 2019] POST /login/ => generated 290 bytes in 127354 msecs (HTTP/1.1 500) 2 headers in 84 bytes (1 switches on core 0)
未登录
[pid: 11915|app: 0|req: 45/63] 58.217.103.52 () {38 vars in 540 bytes} [Wed Oct 23 21:27:06 2019] POST /get_schedule/ => generated 9230 bytes in 879 msecs (HTTP/1.1 200) 2 headers in 73 bytes (1 switches on core 0)
未登录
[pid: 11915|app: 0|req: 46/64] 58.217.103.52 () {38 vars in 540 bytes} [Wed Oct 23 21:27:12 2019] POST /get_schedule/ => generated 9230 bytes in 926 msecs (HTTP/1.1 200) 2 headers in 73 bytes (1 switches on core 1)
已登录
[pid: 11915|app: 0|req: 47/65] 58.217.103.52 () {38 vars in 539 bytes} [Wed Oct 23 21:27:16 2019] POST /get_schedule/ => generated 9230 bytes in 1313 msecs (HTTP/1.1 200) 2 headers in 73 bytes (1 switches on core 0)
已登录
[pid: 11915|app: 0|req: 48/66] 58.217.103.52 () {38 vars in 540 bytes} [Wed Oct 23 21:27:22 2019] POST /get_schedule/ => generated 9230 bytes in 1062 msecs (HTTP/1.1 200) 2 headers in 73 bytes (1 switches on core 1)
[pid: 11915|app: 0|req: 49/67] 216.218.206.67 () {28 vars in 306 bytes} [Wed Oct 23 21:40:07 2019] GET / => generated 336 bytes in 0 msecs (HTTP/1.1 200) 2 headers in 80 bytes (1 switches on core 0)
[pid: 11915|app: 0|req: 50/68] 117.136.67.251 () {40 vars in 900 bytes} [Wed Oct 23 21:43:07 2019] GET / => generated 336 bytes in 0 msecs (HTTP/1.1 200) 2 headers in 80 bytes (1 switches on core 0)
[pid: 11913|app: 0|req: 19/69] 117.136.67.251 () {40 vars in 873 bytes} [Wed Oct 23 21:43:07 2019] GET /favicon.ico => generated 232 bytes in 0 msecs (HTTP/1.1 404) 2 headers in 72 bytes (1 switches on core 1)
[pid: 11915|app: 0|req: 51/70] 117.136.67.251 () {40 vars in 900 bytes} [Wed Oct 23 21:43:26 2019] GET / => generated 336 bytes in 0 msecs (HTTP/1.1 200) 2 headers in 80 bytes (1 switches on core 0)
[pid: 11913|app: 0|req: 20/71] 117.136.67.251 () {40 vars in 873 bytes} [Wed Oct 23 21:43:26 2019] GET /favicon.ico => generated 232 bytes in 0 msecs (HTTP/1.1 404) 2 headers in 72 bytes (1 switches on core 1)
[pid: 11915|app: 0|req: 52/72] 122.96.42.156 () {40 vars in 905 bytes} [Wed Oct 23 21:43:31 2019] GET / => generated 336 bytes in 0 msecs (HTTP/1.1 200) 2 headers in 80 bytes (1 switches on core 0)
[pid: 11913|app: 0|req: 21/73] 122.96.42.156 () {40 vars in 878 bytes} [Wed Oct 23 21:43:31 2019] GET /favicon.ico => generated 232 bytes in 1 msecs (HTTP/1.1 404) 2 headers in 72 bytes (1 switches on core 1)
[pid: 11915|app: 0|req: 53/74] 223.166.151.191 () {36 vars in 561 bytes} [Wed Oct 23 21:44:00 2019] GET / => generated 336 bytes in 0 msecs (HTTP/1.1 200) 2 headers in 80 bytes (1 switches on core 0)
[pid: 11915|app: 0|req: 54/75] 122.96.42.156 () {40 vars in 905 bytes} [Wed Oct 23 21:45:43 2019] GET / => generated 336 bytes in 0 msecs (HTTP/1.1 200) 2 headers in 80 bytes (1 switches on core 0)
[pid: 11915|app: 0|req: 55/76] 122.96.42.156 () {40 vars in 878 bytes} [Wed Oct 23 21:45:43 2019] GET /favicon.ico => generated 232 bytes in 0 msecs (HTTP/1.1 404) 2 headers in 72 bytes (1 switches on core 0)
[pid: 11915|app: 0|req: 56/77] 153.101.248.122 () {42 vars in 742 bytes} [Wed Oct 23 21:45:57 2019] GET / => generated 336 bytes in 0 msecs (HTTP/1.1 200) 2 headers in 80 bytes (1 switches on core 0)
[2019-10-23 21:50:52,591] ERROR in app: Exception on /login/ [POST]
Traceback (most recent call last):
  File "/usr/local/python3/lib/python3.6/site-packages/urllib3/connection.py", line 157, in _new_conn
    (self._dns_host, self.port), self.timeout, **extra_kw
  File "/usr/local/python3/lib/python3.6/site-packages/urllib3/util/connection.py", line 84, in create_connection
    raise err
  File "/usr/local/python3/lib/python3.6/site-packages/urllib3/util/connection.py", line 74, in create_connection
    sock.connect(sa)
TimeoutError: [Errno 110] Connection timed out

During handling of the above exception, another exception occurred:

Traceback (most recent call last):
  File "/usr/local/python3/lib/python3.6/site-packages/urllib3/connectionpool.py", line 672, in urlopen
    chunked=chunked,
  File "/usr/local/python3/lib/python3.6/site-packages/urllib3/connectionpool.py", line 376, in _make_request
    self._validate_conn(conn)
  File "/usr/local/python3/lib/python3.6/site-packages/urllib3/connectionpool.py", line 994, in _validate_conn
    conn.connect()
  File "/usr/local/python3/lib/python3.6/site-packages/urllib3/connection.py", line 334, in connect
    conn = self._new_conn()
  File "/usr/local/python3/lib/python3.6/site-packages/urllib3/connection.py", line 169, in _new_conn
    self, "Failed to establish a new connection: %s" % e
urllib3.exceptions.NewConnectionError: <urllib3.connection.VerifiedHTTPSConnection object at 0x7f7740656cf8>: Failed to establish a new connection: [Errno 110] Connection timed out

During handling of the above exception, another exception occurred:

Traceback (most recent call last):
  File "/usr/local/python3/lib/python3.6/site-packages/requests/adapters.py", line 449, in send
    timeout=timeout
  File "/usr/local/python3/lib/python3.6/site-packages/urllib3/connectionpool.py", line 720, in urlopen
    method, url, error=e, _pool=self, _stacktrace=sys.exc_info()[2]
  File "/usr/local/python3/lib/python3.6/site-packages/urllib3/util/retry.py", line 436, in increment
    raise MaxRetryError(_pool, url, error or ResponseError(cause))
urllib3.exceptions.MaxRetryError: HTTPSConnectionPool(host='vpn.just.edu.cn', port=443): Max retries exceeded with url: /dana-na/auth/url_default/login.cgi (Caused by NewConnectionError('<urllib3.connection.VerifiedHTTPSConnection object at 0x7f7740656cf8>: Failed to establish a new connection: [Errno 110] Connection timed out',))

During handling of the above exception, another exception occurred:

Traceback (most recent call last):
  File "./VPN/vpnAccountManage.py", line 48, in vpn_account_or_useing
    requests.packages.urllib3.disable_warnings()
  File "/usr/local/python3/lib/python3.6/site-packages/requests/sessions.py", line 581, in post
    return self.request('POST', url, data=data, json=json, **kwargs)
  File "/usr/local/python3/lib/python3.6/site-packages/requests/sessions.py", line 533, in request
    resp = self.send(prep, **send_kwargs)
  File "/usr/local/python3/lib/python3.6/site-packages/requests/sessions.py", line 646, in send
    r = adapter.send(request, **kwargs)
  File "/usr/local/python3/lib/python3.6/site-packages/requests/adapters.py", line 516, in send
    raise ConnectionError(e, request=request)
requests.exceptions.ConnectionError: HTTPSConnectionPool(host='vpn.just.edu.cn', port=443): Max retries exceeded with url: /dana-na/auth/url_default/login.cgi (Caused by NewConnectionError('<urllib3.connection.VerifiedHTTPSConnection object at 0x7f7740656cf8>: Failed to establish a new connection: [Errno 110] Connection timed out',))

During handling of the above exception, another exception occurred:

Traceback (most recent call last):
  File "/usr/local/python3/lib/python3.6/site-packages/flask/app.py", line 2446, in wsgi_app
    response = self.full_dispatch_request()
  File "/usr/local/python3/lib/python3.6/site-packages/flask/app.py", line 1951, in full_dispatch_request
    rv = self.handle_user_exception(e)
  File "/usr/local/python3/lib/python3.6/site-packages/flask/app.py", line 1820, in handle_user_exception
    reraise(exc_type, exc_value, tb)
  File "/usr/local/python3/lib/python3.6/site-packages/flask/_compat.py", line 39, in reraise
    raise value
  File "/usr/local/python3/lib/python3.6/site-packages/flask/app.py", line 1949, in full_dispatch_request
    rv = self.dispatch_request()
  File "/usr/local/python3/lib/python3.6/site-packages/flask/app.py", line 1935, in dispatch_request
    return self.view_functions[rule.endpoint](**req.view_args)
  File "/usr/local/webserver/FSS/app.py", line 21, in login
    login_or_success, login_message = JL.login_vpn()
  File "./UserLogin/UserOperator.py", line 38, in login_vpn
    v_username, v_password = VA.get_can_use_account()
  File "./VPN/vpnAccountManage.py", line 87, in get_can_use_account
    stats = self.vpn_account_or_useing(username, password)
  File "./VPN/vpnAccountManage.py", line 50, in vpn_account_or_useing
    except Exception as e:
Exception: 连接失败:HTTPSConnectionPool(host='vpn.just.edu.cn', port=443): Max retries exceeded with url: /dana-na/auth/url_default/login.cgi (Caused by NewConnectionError('<urllib3.connection.VerifiedHTTPSConnection object at 0x7f7740656cf8>: Failed to establish a new connection: [Errno 110] Connection timed out',))
[pid: 11915|app: 0|req: 58/78] 153.101.248.122 () {38 vars in 527 bytes} [Wed Oct 23 21:48:45 2019] POST /login/ => generated 290 bytes in 127336 msecs (HTTP/1.1 500) 2 headers in 84 bytes (1 switches on core 0)
[pid: 11915|app: 0|req: 59/79] 122.96.42.156 () {40 vars in 905 bytes} [Wed Oct 23 21:50:56 2019] GET / => generated 336 bytes in 0 msecs (HTTP/1.1 200) 2 headers in 80 bytes (1 switches on core 0)
[pid: 11915|app: 0|req: 60/80] 122.96.42.156 () {40 vars in 878 bytes} [Wed Oct 23 21:50:56 2019] GET /favicon.ico => generated 232 bytes in 0 msecs (HTTP/1.1 404) 2 headers in 72 bytes (1 switches on core 0)
[2019-10-23 21:51:04,239] ERROR in app: Exception on /login/ [POST]
Traceback (most recent call last):
  File "/usr/local/python3/lib/python3.6/site-packages/urllib3/connection.py", line 157, in _new_conn
    (self._dns_host, self.port), self.timeout, **extra_kw
  File "/usr/local/python3/lib/python3.6/site-packages/urllib3/util/connection.py", line 84, in create_connection
    raise err
  File "/usr/local/python3/lib/python3.6/site-packages/urllib3/util/connection.py", line 74, in create_connection
    sock.connect(sa)
TimeoutError: [Errno 110] Connection timed out

During handling of the above exception, another exception occurred:

Traceback (most recent call last):
  File "/usr/local/python3/lib/python3.6/site-packages/urllib3/connectionpool.py", line 672, in urlopen
    chunked=chunked,
  File "/usr/local/python3/lib/python3.6/site-packages/urllib3/connectionpool.py", line 376, in _make_request
    self._validate_conn(conn)
  File "/usr/local/python3/lib/python3.6/site-packages/urllib3/connectionpool.py", line 994, in _validate_conn
    conn.connect()
  File "/usr/local/python3/lib/python3.6/site-packages/urllib3/connection.py", line 334, in connect
    conn = self._new_conn()
  File "/usr/local/python3/lib/python3.6/site-packages/urllib3/connection.py", line 169, in _new_conn
    self, "Failed to establish a new connection: %s" % e
urllib3.exceptions.NewConnectionError: <urllib3.connection.VerifiedHTTPSConnection object at 0x7f7740670080>: Failed to establish a new connection: [Errno 110] Connection timed out

During handling of the above exception, another exception occurred:

Traceback (most recent call last):
  File "/usr/local/python3/lib/python3.6/site-packages/requests/adapters.py", line 449, in send
    timeout=timeout
  File "/usr/local/python3/lib/python3.6/site-packages/urllib3/connectionpool.py", line 720, in urlopen
    method, url, error=e, _pool=self, _stacktrace=sys.exc_info()[2]
  File "/usr/local/python3/lib/python3.6/site-packages/urllib3/util/retry.py", line 436, in increment
    raise MaxRetryError(_pool, url, error or ResponseError(cause))
urllib3.exceptions.MaxRetryError: HTTPSConnectionPool(host='vpn.just.edu.cn', port=443): Max retries exceeded with url: /dana-na/auth/url_default/login.cgi (Caused by NewConnectionError('<urllib3.connection.VerifiedHTTPSConnection object at 0x7f7740670080>: Failed to establish a new connection: [Errno 110] Connection timed out',))

During handling of the above exception, another exception occurred:

Traceback (most recent call last):
  File "./VPN/vpnAccountManage.py", line 48, in vpn_account_or_useing
    requests.packages.urllib3.disable_warnings()
  File "/usr/local/python3/lib/python3.6/site-packages/requests/sessions.py", line 581, in post
    return self.request('POST', url, data=data, json=json, **kwargs)
  File "/usr/local/python3/lib/python3.6/site-packages/requests/sessions.py", line 533, in request
    resp = self.send(prep, **send_kwargs)
  File "/usr/local/python3/lib/python3.6/site-packages/requests/sessions.py", line 646, in send
    r = adapter.send(request, **kwargs)
  File "/usr/local/python3/lib/python3.6/site-packages/requests/adapters.py", line 516, in send
    raise ConnectionError(e, request=request)
requests.exceptions.ConnectionError: HTTPSConnectionPool(host='vpn.just.edu.cn', port=443): Max retries exceeded with url: /dana-na/auth/url_default/login.cgi (Caused by NewConnectionError('<urllib3.connection.VerifiedHTTPSConnection object at 0x7f7740670080>: Failed to establish a new connection: [Errno 110] Connection timed out',))

During handling of the above exception, another exception occurred:

Traceback (most recent call last):
  File "/usr/local/python3/lib/python3.6/site-packages/flask/app.py", line 2446, in wsgi_app
    response = self.full_dispatch_request()
  File "/usr/local/python3/lib/python3.6/site-packages/flask/app.py", line 1951, in full_dispatch_request
    rv = self.handle_user_exception(e)
  File "/usr/local/python3/lib/python3.6/site-packages/flask/app.py", line 1820, in handle_user_exception
    reraise(exc_type, exc_value, tb)
  File "/usr/local/python3/lib/python3.6/site-packages/flask/_compat.py", line 39, in reraise
    raise value
  File "/usr/local/python3/lib/python3.6/site-packages/flask/app.py", line 1949, in full_dispatch_request
    rv = self.dispatch_request()
  File "/usr/local/python3/lib/python3.6/site-packages/flask/app.py", line 1935, in dispatch_request
    return self.view_functions[rule.endpoint](**req.view_args)
  File "/usr/local/webserver/FSS/app.py", line 21, in login
    login_or_success, login_message = JL.login_vpn()
  File "./UserLogin/UserOperator.py", line 38, in login_vpn
    v_username, v_password = VA.get_can_use_account()
  File "./VPN/vpnAccountManage.py", line 87, in get_can_use_account
    stats = self.vpn_account_or_useing(username, password)
  File "./VPN/vpnAccountManage.py", line 50, in vpn_account_or_useing
    except Exception as e:
Exception: 连接失败:HTTPSConnectionPool(host='vpn.just.edu.cn', port=443): Max retries exceeded with url: /dana-na/auth/url_default/login.cgi (Caused by NewConnectionError('<urllib3.connection.VerifiedHTTPSConnection object at 0x7f7740670080>: Failed to establish a new connection: [Errno 110] Connection timed out',))
[pid: 11915|app: 0|req: 60/81] 153.101.248.122 () {38 vars in 527 bytes} [Wed Oct 23 21:48:56 2019] POST /login/ => generated 290 bytes in 127279 msecs (HTTP/1.1 500) 2 headers in 84 bytes (1 switches on core 1)
已登录
[pid: 11915|app: 0|req: 61/82] 153.101.248.122 () {38 vars in 527 bytes} [Wed Oct 23 21:51:55 2019] POST /login/ => generated 85 bytes in 1101 msecs (HTTP/1.1 200) 2 headers in 71 bytes (1 switches on core 0)
[2019-10-23 21:52:30,383] ERROR in app: Exception on /login/ [POST]
Traceback (most recent call last):
  File "/usr/local/python3/lib/python3.6/site-packages/urllib3/connection.py", line 157, in _new_conn
    (self._dns_host, self.port), self.timeout, **extra_kw
  File "/usr/local/python3/lib/python3.6/site-packages/urllib3/util/connection.py", line 84, in create_connection
    raise err
  File "/usr/local/python3/lib/python3.6/site-packages/urllib3/util/connection.py", line 74, in create_connection
    sock.connect(sa)
TimeoutError: [Errno 110] Connection timed out

During handling of the above exception, another exception occurred:

Traceback (most recent call last):
  File "/usr/local/python3/lib/python3.6/site-packages/urllib3/connectionpool.py", line 672, in urlopen
    chunked=chunked,
  File "/usr/local/python3/lib/python3.6/site-packages/urllib3/connectionpool.py", line 376, in _make_request
    self._validate_conn(conn)
  File "/usr/local/python3/lib/python3.6/site-packages/urllib3/connectionpool.py", line 994, in _validate_conn
    conn.connect()
  File "/usr/local/python3/lib/python3.6/site-packages/urllib3/connection.py", line 334, in connect
    conn = self._new_conn()
  File "/usr/local/python3/lib/python3.6/site-packages/urllib3/connection.py", line 169, in _new_conn
    self, "Failed to establish a new connection: %s" % e
urllib3.exceptions.NewConnectionError: <urllib3.connection.VerifiedHTTPSConnection object at 0x7f7740c4afd0>: Failed to establish a new connection: [Errno 110] Connection timed out

During handling of the above exception, another exception occurred:

Traceback (most recent call last):
  File "/usr/local/python3/lib/python3.6/site-packages/requests/adapters.py", line 449, in send
    timeout=timeout
  File "/usr/local/python3/lib/python3.6/site-packages/urllib3/connectionpool.py", line 720, in urlopen
    method, url, error=e, _pool=self, _stacktrace=sys.exc_info()[2]
  File "/usr/local/python3/lib/python3.6/site-packages/urllib3/util/retry.py", line 436, in increment
    raise MaxRetryError(_pool, url, error or ResponseError(cause))
urllib3.exceptions.MaxRetryError: HTTPSConnectionPool(host='vpn.just.edu.cn', port=443): Max retries exceeded with url: /dana-na/auth/url_default/login.cgi (Caused by NewConnectionError('<urllib3.connection.VerifiedHTTPSConnection object at 0x7f7740c4afd0>: Failed to establish a new connection: [Errno 110] Connection timed out',))

During handling of the above exception, another exception occurred:

Traceback (most recent call last):
  File "./VPN/vpnAccountManage.py", line 48, in vpn_account_or_useing
    requests.packages.urllib3.disable_warnings()
  File "/usr/local/python3/lib/python3.6/site-packages/requests/sessions.py", line 581, in post
    return self.request('POST', url, data=data, json=json, **kwargs)
  File "/usr/local/python3/lib/python3.6/site-packages/requests/sessions.py", line 533, in request
    resp = self.send(prep, **send_kwargs)
  File "/usr/local/python3/lib/python3.6/site-packages/requests/sessions.py", line 646, in send
    r = adapter.send(request, **kwargs)
  File "/usr/local/python3/lib/python3.6/site-packages/requests/adapters.py", line 516, in send
    raise ConnectionError(e, request=request)
requests.exceptions.ConnectionError: HTTPSConnectionPool(host='vpn.just.edu.cn', port=443): Max retries exceeded with url: /dana-na/auth/url_default/login.cgi (Caused by NewConnectionError('<urllib3.connection.VerifiedHTTPSConnection object at 0x7f7740c4afd0>: Failed to establish a new connection: [Errno 110] Connection timed out',))

During handling of the above exception, another exception occurred:

Traceback (most recent call last):
  File "/usr/local/python3/lib/python3.6/site-packages/flask/app.py", line 2446, in wsgi_app
    response = self.full_dispatch_request()
  File "/usr/local/python3/lib/python3.6/site-packages/flask/app.py", line 1951, in full_dispatch_request
    rv = self.handle_user_exception(e)
  File "/usr/local/python3/lib/python3.6/site-packages/flask/app.py", line 1820, in handle_user_exception
    reraise(exc_type, exc_value, tb)
  File "/usr/local/python3/lib/python3.6/site-packages/flask/_compat.py", line 39, in reraise
    raise value
  File "/usr/local/python3/lib/python3.6/site-packages/flask/app.py", line 1949, in full_dispatch_request
    rv = self.dispatch_request()
  File "/usr/local/python3/lib/python3.6/site-packages/flask/app.py", line 1935, in dispatch_request
    return self.view_functions[rule.endpoint](**req.view_args)
  File "/usr/local/webserver/FSS/app.py", line 21, in login
    login_or_success, login_message = JL.login_vpn()
  File "./UserLogin/UserOperator.py", line 38, in login_vpn
    v_username, v_password = VA.get_can_use_account()
  File "./VPN/vpnAccountManage.py", line 87, in get_can_use_account
    stats = self.vpn_account_or_useing(username, password)
  File "./VPN/vpnAccountManage.py", line 50, in vpn_account_or_useing
    except Exception as e:
Exception: 连接失败:HTTPSConnectionPool(host='vpn.just.edu.cn', port=443): Max retries exceeded with url: /dana-na/auth/url_default/login.cgi (Caused by NewConnectionError('<urllib3.connection.VerifiedHTTPSConnection object at 0x7f7740c4afd0>: Failed to establish a new connection: [Errno 110] Connection timed out',))
[pid: 11913|app: 0|req: 23/83] 153.101.248.122 () {38 vars in 527 bytes} [Wed Oct 23 21:50:23 2019] POST /login/ => generated 290 bytes in 127383 msecs (HTTP/1.1 500) 2 headers in 84 bytes (1 switches on core 1)
[2019-10-23 21:52:53,423] ERROR in app: Exception on /login/ [POST]
Traceback (most recent call last):
  File "/usr/local/python3/lib/python3.6/site-packages/urllib3/connection.py", line 157, in _new_conn
    (self._dns_host, self.port), self.timeout, **extra_kw
  File "/usr/local/python3/lib/python3.6/site-packages/urllib3/util/connection.py", line 84, in create_connection
    raise err
  File "/usr/local/python3/lib/python3.6/site-packages/urllib3/util/connection.py", line 74, in create_connection
    sock.connect(sa)
TimeoutError: [Errno 110] Connection timed out

During handling of the above exception, another exception occurred:

Traceback (most recent call last):
  File "/usr/local/python3/lib/python3.6/site-packages/urllib3/connectionpool.py", line 672, in urlopen
    chunked=chunked,
  File "/usr/local/python3/lib/python3.6/site-packages/urllib3/connectionpool.py", line 376, in _make_request
    self._validate_conn(conn)
  File "/usr/local/python3/lib/python3.6/site-packages/urllib3/connectionpool.py", line 994, in _validate_conn
    conn.connect()
  File "/usr/local/python3/lib/python3.6/site-packages/urllib3/connection.py", line 334, in connect
    conn = self._new_conn()
  File "/usr/local/python3/lib/python3.6/site-packages/urllib3/connection.py", line 169, in _new_conn
    self, "Failed to establish a new connection: %s" % e
urllib3.exceptions.NewConnectionError: <urllib3.connection.VerifiedHTTPSConnection object at 0x7f7740e69dd8>: Failed to establish a new connection: [Errno 110] Connection timed out

During handling of the above exception, another exception occurred:

Traceback (most recent call last):
  File "/usr/local/python3/lib/python3.6/site-packages/requests/adapters.py", line 449, in send
    timeout=timeout
  File "/usr/local/python3/lib/python3.6/site-packages/urllib3/connectionpool.py", line 720, in urlopen
    method, url, error=e, _pool=self, _stacktrace=sys.exc_info()[2]
  File "/usr/local/python3/lib/python3.6/site-packages/urllib3/util/retry.py", line 436, in increment
    raise MaxRetryError(_pool, url, error or ResponseError(cause))
urllib3.exceptions.MaxRetryError: HTTPSConnectionPool(host='vpn.just.edu.cn', port=443): Max retries exceeded with url: /dana-na/auth/url_default/login.cgi (Caused by NewConnectionError('<urllib3.connection.VerifiedHTTPSConnection object at 0x7f7740e69dd8>: Failed to establish a new connection: [Errno 110] Connection timed out',))

During handling of the above exception, another exception occurred:

Traceback (most recent call last):
  File "./VPN/vpnAccountManage.py", line 48, in vpn_account_or_useing
    requests.packages.urllib3.disable_warnings()
  File "/usr/local/python3/lib/python3.6/site-packages/requests/sessions.py", line 581, in post
    return self.request('POST', url, data=data, json=json, **kwargs)
  File "/usr/local/python3/lib/python3.6/site-packages/requests/sessions.py", line 533, in request
    resp = self.send(prep, **send_kwargs)
  File "/usr/local/python3/lib/python3.6/site-packages/requests/sessions.py", line 646, in send
    r = adapter.send(request, **kwargs)
  File "/usr/local/python3/lib/python3.6/site-packages/requests/adapters.py", line 516, in send
    raise ConnectionError(e, request=request)
requests.exceptions.ConnectionError: HTTPSConnectionPool(host='vpn.just.edu.cn', port=443): Max retries exceeded with url: /dana-na/auth/url_default/login.cgi (Caused by NewConnectionError('<urllib3.connection.VerifiedHTTPSConnection object at 0x7f7740e69dd8>: Failed to establish a new connection: [Errno 110] Connection timed out',))

During handling of the above exception, another exception occurred:

Traceback (most recent call last):
  File "/usr/local/python3/lib/python3.6/site-packages/flask/app.py", line 2446, in wsgi_app
    response = self.full_dispatch_request()
  File "/usr/local/python3/lib/python3.6/site-packages/flask/app.py", line 1951, in full_dispatch_request
    rv = self.handle_user_exception(e)
  File "/usr/local/python3/lib/python3.6/site-packages/flask/app.py", line 1820, in handle_user_exception
    reraise(exc_type, exc_value, tb)
  File "/usr/local/python3/lib/python3.6/site-packages/flask/_compat.py", line 39, in reraise
    raise value
  File "/usr/local/python3/lib/python3.6/site-packages/flask/app.py", line 1949, in full_dispatch_request
    rv = self.dispatch_request()
  File "/usr/local/python3/lib/python3.6/site-packages/flask/app.py", line 1935, in dispatch_request
    return self.view_functions[rule.endpoint](**req.view_args)
  File "/usr/local/webserver/FSS/app.py", line 21, in login
    login_or_success, login_message = JL.login_vpn()
  File "./UserLogin/UserOperator.py", line 38, in login_vpn
    v_username, v_password = VA.get_can_use_account()
  File "./VPN/vpnAccountManage.py", line 87, in get_can_use_account
    stats = self.vpn_account_or_useing(username, password)
  File "./VPN/vpnAccountManage.py", line 50, in vpn_account_or_useing
    except Exception as e:
Exception: 连接失败:HTTPSConnectionPool(host='vpn.just.edu.cn', port=443): Max retries exceeded with url: /dana-na/auth/url_default/login.cgi (Caused by NewConnectionError('<urllib3.connection.VerifiedHTTPSConnection object at 0x7f7740e69dd8>: Failed to establish a new connection: [Errno 110] Connection timed out',))
[pid: 11913|app: 0|req: 23/84] 153.101.248.122 () {38 vars in 527 bytes} [Wed Oct 23 21:50:46 2019] POST /login/ => generated 290 bytes in 127332 msecs (HTTP/1.1 500) 2 headers in 84 bytes (1 switches on core 0)
[pid: 11915|app: 0|req: 62/85] 2.187.92.9 () {32 vars in 461 bytes} [Wed Oct 23 21:57:35 2019] GET / => generated 336 bytes in 0 msecs (HTTP/1.1 200) 2 headers in 80 bytes (1 switches on core 1)
[pid: 11913|app: 0|req: 24/86] 2.187.92.9 () {32 vars in 461 bytes} [Wed Oct 23 21:57:35 2019] GET / => generated 336 bytes in 0 msecs (HTTP/1.1 200) 2 headers in 80 bytes (1 switches on core 1)
Wed Oct 23 21:58:57 2019 - *** /usr/local/webserver/FSS/ has been touched... grace them all !!! ***
...gracefully killing workers...
Gracefully killing worker 1 (pid: 11913)...
Gracefully killing worker 2 (pid: 11915)...
worker 1 buried after 1 seconds
worker 2 buried after 1 seconds
binary reloading uWSGI...
chdir() to /usr/local/webserver/FSS
closing all non-uwsgi socket fds > 2 (max_fd = 100001)...
found fd 6 mapped to socket 0 (127.0.0.1:8081)
running /usr/local/python3/bin/uwsgi
[uWSGI] getting INI configuration from uwsgi.ini
*** Starting uWSGI 2.0.18 (64bit) on [Wed Oct 23 21:58:58 2019] ***
compiled with version: 4.8.5 20150623 (Red Hat 4.8.5-39) on 21 October 2019 12:48:53
os: Linux-3.10.0-957.21.3.el7.x86_64 #1 SMP Tue Jun 18 16:35:19 UTC 2019
nodename: VM_0_6_centos
machine: x86_64
clock source: unix
pcre jit disabled
detected number of CPU cores: 1
current working directory: /usr/local/webserver/FSS
detected binary path: /usr/local/python3/bin/uwsgi
uWSGI running as root, you can use --uid/--gid/--chroot options
*** WARNING: you are running uWSGI as root !!! (use the --uid flag) *** 
chdir() to /usr/local/webserver/FSS/
your processes number limit is 7269
your memory page size is 4096 bytes
detected max file descriptor number: 100001
lock engine: pthread robust mutexes
thunder lock: disabled (you can enable it with --thunder-lock)
uwsgi socket 0 inherited INET address 127.0.0.1:8081 fd 6
uWSGI running as root, you can use --uid/--gid/--chroot options
*** WARNING: you are running uWSGI as root !!! (use the --uid flag) *** 
Python version: 3.6.1 (default, Oct 19 2019, 16:14:38)  [GCC 4.8.5 20150623 (Red Hat 4.8.5-36)]
Python main interpreter initialized at 0xce0f40
uWSGI running as root, you can use --uid/--gid/--chroot options
*** WARNING: you are running uWSGI as root !!! (use the --uid flag) *** 
python threads support enabled
your server socket listen backlog is limited to 100 connections
your mercy for graceful operations on workers is 60 seconds
mapped 250128 bytes (244 KB) for 4 cores
*** Operational MODE: preforking+threaded ***
WSGI app 0 (mountpoint='') ready in 0 seconds on interpreter 0xce0f40 pid: 9740 (default app)
uWSGI running as root, you can use --uid/--gid/--chroot options
*** WARNING: you are running uWSGI as root !!! (use the --uid flag) *** 
*** uWSGI is running in multiple interpreter mode ***
gracefully (RE)spawned uWSGI master process (pid: 9740)
spawned uWSGI worker 1 (pid: 27038, cores: 2)
spawned uWSGI worker 2 (pid: 27039, cores: 2)
Wed Oct 23 21:59:16 2019 - *** /usr/local/webserver/FSS/ has been touched... grace them all !!! ***
...gracefully killing workers...
Gracefully killing worker 1 (pid: 27038)...
Gracefully killing worker 2 (pid: 27039)...
worker 1 buried after 1 seconds
worker 2 buried after 1 seconds
binary reloading uWSGI...
chdir() to /usr/local/webserver/FSS
closing all non-uwsgi socket fds > 2 (max_fd = 100001)...
found fd 6 mapped to socket 0 (127.0.0.1:8081)
running /usr/local/python3/bin/uwsgi
[uWSGI] getting INI configuration from uwsgi.ini
*** Starting uWSGI 2.0.18 (64bit) on [Wed Oct 23 21:59:17 2019] ***
compiled with version: 4.8.5 20150623 (Red Hat 4.8.5-39) on 21 October 2019 12:48:53
os: Linux-3.10.0-957.21.3.el7.x86_64 #1 SMP Tue Jun 18 16:35:19 UTC 2019
nodename: VM_0_6_centos
machine: x86_64
clock source: unix
pcre jit disabled
detected number of CPU cores: 1
current working directory: /usr/local/webserver/FSS
detected binary path: /usr/local/python3/bin/uwsgi
uWSGI running as root, you can use --uid/--gid/--chroot options
*** WARNING: you are running uWSGI as root !!! (use the --uid flag) *** 
chdir() to /usr/local/webserver/FSS/
your processes number limit is 7269
your memory page size is 4096 bytes
detected max file descriptor number: 100001
lock engine: pthread robust mutexes
thunder lock: disabled (you can enable it with --thunder-lock)
uwsgi socket 0 inherited INET address 127.0.0.1:8081 fd 6
uWSGI running as root, you can use --uid/--gid/--chroot options
*** WARNING: you are running uWSGI as root !!! (use the --uid flag) *** 
Python version: 3.6.1 (default, Oct 19 2019, 16:14:38)  [GCC 4.8.5 20150623 (Red Hat 4.8.5-36)]
Python main interpreter initialized at 0x29580a0
uWSGI running as root, you can use --uid/--gid/--chroot options
*** WARNING: you are running uWSGI as root !!! (use the --uid flag) *** 
python threads support enabled
your server socket listen backlog is limited to 100 connections
your mercy for graceful operations on workers is 60 seconds
mapped 250128 bytes (244 KB) for 4 cores
*** Operational MODE: preforking+threaded ***
WSGI app 0 (mountpoint='') ready in 0 seconds on interpreter 0x29580a0 pid: 9740 (default app)
uWSGI running as root, you can use --uid/--gid/--chroot options
*** WARNING: you are running uWSGI as root !!! (use the --uid flag) *** 
*** uWSGI is running in multiple interpreter mode ***
gracefully (RE)spawned uWSGI master process (pid: 9740)
spawned uWSGI worker 1 (pid: 27114, cores: 2)
spawned uWSGI worker 2 (pid: 27115, cores: 2)
bind(): No such file or directory [core/socket.c line 230]
...brutally killing workers...
Wed Oct 23 21:59:18 2019 - uWSGI worker 1 screams: UAAAAAAH my master disconnected: i will kill myself !!!
Wed Oct 23 21:59:18 2019 - uWSGI worker 2 screams: UAAAAAAH my master disconnected: i will kill myself !!!
*** Starting uWSGI 2.0.18 (64bit) on [Wed Oct 23 21:59:35 2019] ***
compiled with version: 4.8.5 20150623 (Red Hat 4.8.5-39) on 21 October 2019 12:48:53
os: Linux-3.10.0-957.21.3.el7.x86_64 #1 SMP Tue Jun 18 16:35:19 UTC 2019
nodename: VM_0_6_centos
machine: x86_64
clock source: unix
pcre jit disabled
detected number of CPU cores: 1
current working directory: /usr/local/webserver/FSS
writing pidfile to /usr/local/webserver/FSS//uwsgi/uwsgi.pid
open("/usr/local/webserver/FSS//uwsgi/uwsgi.pid"): No such file or directory [core/utils.c line 3616]
*** Starting uWSGI 2.0.18 (64bit) on [Wed Oct 23 22:00:20 2019] ***
compiled with version: 4.8.5 20150623 (Red Hat 4.8.5-39) on 21 October 2019 12:48:53
os: Linux-3.10.0-957.21.3.el7.x86_64 #1 SMP Tue Jun 18 16:35:19 UTC 2019
nodename: VM_0_6_centos
machine: x86_64
clock source: unix
pcre jit disabled
detected number of CPU cores: 1
current working directory: /usr/local/webserver/FSS
writing pidfile to /usr/local/webserver/FSS//uwsgi/uwsgi.pid
open("/usr/local/webserver/FSS//uwsgi/uwsgi.pid"): No such file or directory [core/utils.c line 3616]
